Workbook

Sheet Sheet1
A1: Primary Variables | B1: Secondary Variables | C1: P1 | D1: P2 | E1: P3 | F1: P4 | G1: P5 | H1: P6 | I1: P7 | J1: P8 | K1: P9 | L1: P10 | M1: P11 | N1: P12 | O1: P13
A2: x1 | C2: 1 | D2: 1 | E2: 0 | F2: 0 | G2: 0 | H2: 1 | I2: 1 | J2: 0 | K2: 1 | L2: 1 | M2: 1 | N2: 1 | O2: 1
A3: x1 | C3: 1 | D3: 1 | E3: 1 | F3: 1 | G3: 1 | H3: 1 | I3: 1 | J3: 1 | K3: 1 | L3: 1 | M3: 1 | N3: 1 | O3: 1
A4: x1 | C4: 1 | D4: 1 | E4: 1 | F4: 1 | G4: 0 | H4: 1 | I4: 1 | J4: 1 | K4: 1 | L4: 1 | M4: 1 | N4: 1 | O4: 1
A5: x1 | C5: 1 | D5: 1 | E5: 1 | F5: 1 | G5: 1 | H5: 1 | I5: 1 | J5: 1 | K5: 1 | L5: 1 | M5: 1 | N5: 1 | O5: 1
A6: x1 | C6: 1 | D6: 0 | E6: 0 | F6: 1 | G6: 0 | H6: 1 | I6: 0 | J6: 1 | K6: 1 | L6: 1 | M6: 0 | N6: 0 | O6: 0
A7: x2 | C7: 1 | D7: 1 | E7: 1 | F7: 0 | G7: 0 | H7: 0 | I7: 0 | J7: 0 | K7: 0 | L7: 0 | M7: 0 | N7: 1 | O7: 0
A8: x2 | C8: 1 | D8: 1 | E8: 1 | F8: 0 | G8: 0 | H8: 0 | I8: 0 | J8: 1 | K8: 0 | L8: 0 | M8: 0 | N8: 1 | O8: 0
A9: x2 | C9: 1 | D9: 1 | E9: 1 | F9: 1 | G9: 1 | H9: 1 | I9: 1 | J9: 1 | K9: 1 | L9: 1 | M9: 1 | N9: 1 | O9: 1
A10: x3 | C10: 1 | D10: 1 | E10: 0 | F10: 1 | G10: 0 | H10: 1 | I10: 1 | J10: 1 | K10: 1 | L10: 1 | M10: 1 | N10: 0 | O10: 1
A11: x3 | C11: 0 | D11: 0 | E11: 1 | F11: 1 | G11: 1 | H11: 1 | I11: 1 | J11: 1 | K11: 1 | L11: 1 | M11: 1 | N11: 1 | O11: 1
A12: x4 | C12: 0 | D12: 1 | E12: 0 | F12: 0 | G12: 0 | H12: 0 | I12: 0 | J12: 0 | K12: 0 | L12: 0 | M12: 0 | N12: 0 | O12: 0
A13: x4 | C13: 1 | D13: 0 | E13: 1 | F13: 0 | G13: 0 | H13: 0 | I13: 0 | J13: 0 | K13: 0 | L13: 0 | M13: 0 | N13: 0 | O13: 0
... A34: x9 | C34: 1 | D34: 1 | E34: 1 | F34: 0 | G34: 0 | H34: 1 | I34: 1 | J34: 0 | K34: 1 | L34: 1 | M34: 1 | N34: 1 | O34: 0

Sheet cor
B1: p1 | C1: p2 | D1: p3 | E1: p4 | F1: p5 | G1: p6 | H1: p7 | I1: p8 | J1: p9 | K1: p10 | L1: p11 | M1: p12 | N1: p13
A2: p1 | B2: 1
A3: p2 | B3: 0.262 | C3: 1
A4: p3 | B4: 0.44 | C4: 0.0524 | D4: 1
A5: p4 | B5: 0.131 | C5: -0.0524 | D5: 0.05 | E5: 1
A6: p5 | B6: 0.0339 | C6: -0.0271 | D6: 0.336 | E6: 0.516 | F6: 1
A7: p6 | B7: 0.306 | C7: -0.0524 | D7: 0.1 | E7: 0.667 | F7: 0.516 | G7: 1
A8: p7 | B8: -0.019 | C8: 0.0151 | D8: 0.13 | E8: 0.577 | F8: 0.534 | G8: 0.593 | H8: 1
A9: p8 | B9: 0.105 | C9: 0.07 | D9: 0.0134 | E9: 0.668 | F9: 0.575 | G9: 0.46 | H9: 0.244 | I9: 1
A10: p9 | B10: 0.102 | C10: -0.0125 | D10: -0.0418 | E10: 0.598 | F10: 0.463 | G10: 0.896 | H10: 0.69 | I10: 0.383 | J10: 1
A11: p10 | B11: 0.223 | C11: -0.121 | D11: 0.175 | E11: 0.5 | F11: 0.478 | G11: 0.833 | H11: 0.606 | I11: 0.454 | J11: 0.747 | K11: 1
A12: p11 | B12: 0.223 | C12: 0.225 | D12: 0.175 | E12: 0.65 | F12: 0.478 | G12: 0.833 | H12: 0.606 | I12: 0.454 | J12: 0.747 | K12: 0.67 | L12: 1
A13: p12 | B13: -0.0429 | C13: 0.142 | D13: 0.242 | E13: 0.0933 | F13: 0.193 | G13: 0.202 | H13: 0.484 | I13: 0.0498 | J13: 0.273 | K13: 0.396 | L13: 0.242 | M13: 1
A14: p13 | B14: 0.0806 | C14: 0.189 | D14: -0.0219 | E14: 0.746 | F14: 0.509 | G14: 0.585 | H14: 0.62 | I14: 0.68 | J14: 0.524 | K14: 0.557 | L14: 0.702 | M14: 0.278 | N14: 1
A18: Means | B18: =AVERAGE(B3:B14,C4:C14,D5:D14,E6:E14,F7:F14,G8:G14,H9:H14,I10:I14,J11:J14,K12:K14,L13:L14,M14) -> 0.34616026
A19: Count | B19: =COUNT(B3:B14,C4:C14,D5:D14,E6:E14,F7:F14,G8:G14,H9:H14,I10:I14,J11:J14,K12:K14,L13:L14,M14) -> 78

Sheet 转置
A1: X1.1 | B1: X1.2 | C1: X1.3 | D1: X1.4 | E1: X1.5 | F1: X2.1 | G1: X2.2 | H1: X2.3 | I1: X3.1 | J1: X3.2 | K1: X4.1 | L1: X4.2 | M1: X4.3 | N1: X5.1 | O1: X5.2 | P1: X5.3 | Q1: X5.4 | R1: X5.5 | S1: X5.6 | T1: X6.1 | U1: X6.2 | V1: X7.1 | W1: X7.2 | X1: X7.3 | Y1: X7.4 | Z1: X8.1 | AA1: X8.2 | AB1: X8.3 | AC1: X8.4 | AD1: X9.1 | AE1: X9.2 | AF1: X9.3 | AG1: X9.4
A2: 1 | B2: 1 | C2: 1 | D2: 1 | E2: 1 | F2: 1 | G2: 1 | H2: 1 | I2: 1 | J2: 0 | K2: 0 | L2: 1 | M2: 0 | N2: 1 | O2: 1 | P2: 1 | Q2: 1 | R2: 1 | S2: 1 | T2: 1 | U2: 1 | V2: 1 | W2: 1 | X2: 0 | Y2: 1 | Z2: 1 | AA2: 1 | AB2: 1 | AC2: 1 | AD2: 1 | AE2: 1 | AF2: 1 | AG2: 1
A3: 1 | B3: 1 | C3: 1 | D3: 1 | E3: 0 | F3: 1 | G3: 1 | H3: 1 | I3: 1 | J3: 0 | K3: 1 | L3: 0 | M3: 0 | N3: 1 | O3: 1 | P3: 1 | Q3: 1 | R3: 1 | S3: 1 | T3: 1 | U3: 1 | V3: 1 | W3: 1 | X3: 1 | Y3: 1 | Z3: 0 | AA3: 1 | AB3: 0 | AC3: 0 | AD3: 1 | AE3: 1 | AF3: 1 | AG3: 1
A4: 0 | B4: 1 | C4: 1 | D4: 1 | E4: 0 | F4: 1 | G4: 1 | H4: 1 | I4: 0 | J4: 1 | K4: 0 | L4: 1 | M4: 0 | N4: 1 | O4: 1 | P4: 1 | Q4: 1 | R4: 0 | S4: 1 | T4: 1 | U4: 0 | V4: 1 | W4: 1 | X4: 0 | Y4: 1 | Z4: 1 | AA4: 1 | AB4: 1 | AC4: 1 | AD4: 1 | AE4: 1 | AF4: 1 | AG4: 1
A5: 0 | B5: 1 | C5: 1 | D5: 1 | E5: 1 | F5: 0 | G5: 0 | H5: 1 | I5: 1 | J5: 1 | K5: 0 | L5: 0 | M5: 1 | N5: 1 | O5: 1 | P5: 0 | Q5: 1 | R5: 1 | S5: 0 | T5: 0 | U5: 1 | V5: 1 | W5: 1 | X5: 0 | Y5: 1 | Z5: 1 | AA5: 1 | AB5: 0 | AC5: 1 | AD5: 1 | AE5: 1 | AF5: 1 | AG5: 0
A6: 0 | B6: 1 | C6: 0 | D6: 1 | E6: 0 | F6: 0 | G6: 0 | H6: 1 | I6: 0 | J6: 1 | K6: 0 | L6: 0 | M6: 1 | N6: 1 | O6: 1 | P6: 1 | Q6: 0 | R6: 0 | S6: 0 | T6: 0 | U6: 1 | V6: 1 | W6: 1 | X6: 0 | Y6: 1 | Z6: 1 | AA6: 1 | AB6: 1 | AC6: 0 | AD6: 1 | AE6: 1 | AF6: 1 | AG6: 0
A7: 1 | B7: 1 | C7: 1 | D7: 1 | E7: 1 | F7: 0 | G7: 0 | H7: 1 | I7: 1 | J7: 1 | K7: 0 | L7: 0 | M7: 1 | N7: 1 | O7: 1 | P7: 1 | Q7: 1 | R7: 1 | S7: 1 | T7: 0 | U7: 1 | V7: 1 | W7: 1 | X7: 0 | Y7: 1 | Z7: 1 | AA7: 1 | AB7: 1 | AC7: 1 | AD7: 1 | AE7: 1 | AF7: 1 | AG7: 1
A8: 1 | B8: 1 | C8: 1 | D8: 1 | E8: 0 | F8: 0 | G8: 0 | H8: 1 | I8: 1 | J8: 1 | K8: 0 | L8: 0 | M8: 1 | N8: 1 | O8: 1 | P8: 0 | Q8: 1 | R8: 0 | S8: 0 | T8: 0 | U8: 1 | V8: 1 | W8: 1 | X8: 1 | Y8: 1 | Z8: 1 | AA8: 1 | AB8: 1 | AC8: 1 | AD8: 1 | AE8: 1 | AF8: 1 | AG8: 1
A9: 0 | B9: 1 | C9: 1 | D9: 1 | E9: 1 | F9: 0 | G9: 1 | H9: 1 | I9: 1 | J9: 1 | K9: 0 | L9: 0 | M9: 1 | N9: 1 | O9: 1 | P9: 1 | Q9: 0 | R9: 1 | S9: 0 | T9: 0 | U9: 1 | V9: 1 | W9: 1 | X9: 0 | Y9: 1 | Z9: 1 | AA9: 0 | AB9: 0 | AC9: 0 | AD9: 1 | AE9: 1 | AF9: 1 | AG9: 0
A10: 1 | B10: 1 | C10: 1 | D10: 1 | E10: 1 | F10: 0 | G10: 0 | H10: 1 | I10: 1 | J10: 1 | K10: 0 | L10: 0 | M10: 1 | N10: 1 | O10: 1 | P10: 1 | Q10: 1 | R10: 1 | S10: 1 | T10: 0 | U10: 1 | V10: 1 | W10: 1 | X10: 1 | Y10: 1 | Z10: 1 | AA10: 1 | AB10: 1 | AC10: 1 | AD10: 1 | AE10: 1 | AF10: 1 | AG10: 1
A11: 1 | B11: 1 | C11: 1 | D11: 1 | E11: 1 | F11: 0 | G11: 0 | H11: 1 | I11: 1 | J11: 1 | K11: 0 | L11: 0 | M11: 1 | N11: 1 | O11: 1 | P11: 1 | Q11: 1 | R11: 0 | S11: 1 | T11: 0 | U11: 1 | V11: 1 | W11: 1 | X11: 0 | Y11: 1 | Z11: 1 | AA11: 0 | AB11: 1 | AC11: 1 | AD11: 1 | AE11: 1 | AF11: 1 | AG11: 1
A12: 1 | B12: 1 | C12: 1 | D12: 1 | E12: 0 | F12: 0 | G12: 0 | H12: 1 | I12: 1 | J12: 1 | K12: 0 | L12: 0 | M12: 1 | N12: 1 | O12: 1 | P12: 1 | Q12: 1 | R12: 1 | S12: 1 | T12: 0 | U12: 1 | V12: 1 | W12: 1 | X12: 0 | Y12: 1 | Z12: 1 | AA12: 1 | AB12: 0 | AC12: 1 | AD12: 1 | AE12: 1 | AF12: 1 | AG12: 1
A13: 1 | B13: 1 | C13: 1 | D13: 1 | E13: 0 | F13: 1 | G13: 1 | H13: 1 | I13: 0 | J13: 1 | K13: 0 | L13: 0 | M13: 1 | N13: 1 | O13: 0 | P13: 0 | Q13: 1 | R13: 0 | S13: 1 | T13: 0 | U13: 1 | V13: 1 | W13: 1 | X13: 1 | Y13: 1 | Z13: 0 | AA13: 0 | AB13: 1 | AC13: 1 | AD13: 1 | AE13: 1 | AF13: 1 | AG13: 1
A14: 1 | B14: 1 | C14: 1 | D14: 1 | E14: 0 | F14: 0 | G14: 0 | H14: 1 | I14: 1 | J14: 1 | K14: 0 | L14: 0 | M14: 1 | N14: 1 | O14: 1 | P14: 0 | Q14: 1 | R14: 1 | S14: 0 | T14: 0 | U14: 1 | V14: 1 | W14: 1 | X14: 0 | Y14: 1 | Z14: 1 | AA14: 0 | AB14: 0 | AC14: 0 | AD14: 1 | AE14: 1 | AF14: 1 | AG14: 0

Sheet Sheet2
A1: Paper_11 | B1: Paper_12 | C1: Paper_13
A2: 0.86 | B2: 0.83 | C2: 1
A3: 0.83 | B3: 0.62 | C3: 0.62
A4: 0.5 | B4: 1 | C4: 1

Sheet Sheet3
A1: Paper_11 | B1: Paper_12 | C1: Paper_13
A2: 0.86 | B2: 1 | C2: 1
A3: 0.83 | B3: 0.62 | C3: 0.62
A4: 0.5 | B4: 0.4 | C4: 1

Sheet Sheet4
A1: Paper_11 | B1: Paper_12 | C1: Paper_13
A2: 0.86 | B2: 1 | C2: 0.3
A3: 1 | B3: 0.62 | C3: 1
A4: 0.5 | B4: 1 | C4: 1

Sheet Sheet5
A1: Paper_11 | B1: Paper_12 | C1: Paper_13
A2: 1 | B2: 1 | C2: 1
A3: 1 | B3: 0.8 | C3: 1
A4: 0.8 | B4: 1 | C4: 1

Sheet 测试
A2: 主要变量 | B2: P1 | C2: P2 | D2: P3 | E2: P4 | F2: P5 | G2: P6 | H2: P7 | I2: P8 | J2: P9 | K2: P10 | L2: P11 | M2: P12 | N2: 平均的
A4: X 1 | B4: 0.8 | C4: 0.8 | D4: 0.8 | E4: 0.8 | F4: 1 | G4: 1 | H4: 0.8 | I4: 0.8 | J4: 0.8 | K4: 1 | L4: 1 | M4: 0.8 | N4: 0.87
A5: X 2 | B5: 0.5 | C5: 0.5 | D5: 0.25 | E5: 0.25 | F5: 0.25 | G5: 0.25 | H5: 0.5 | I5: 0.75 | J5: 0.25 | K5: 0.5 | L5: 0.5 | M5: 0.25 | N5: 0.4
A6: X 3 | B6: 0.67 | C6: 1 | D6: 1 | E6: 1 | F6: 0.67 | G6: 1 | H6: 1 | I6: 1 | J6: 1 | K6: 1 | L6: 1 | M6: 0.67 | N6: 0.92
A7: X 4 | B7: 0.75 | C7: 0.5 | D7: 0.75 | E7: 0 | F7: 0.25 | G7: 0.5 | H7: 0.5 | I7: 0.5 | J7: 0.5 | K7: 0.75 | L7: 0.5 | M7: 0.25 | N7: 0.48
A8: X 5 | B8: 1 | C8: 1 | D8: 1 | E8: 1 | F8: 0.83 | G8: 1 | H8: 1 | I8: 1 | J8: 1 | K8: 1 | L8: 1 | M8: 0.83 | N8: 0.97
A9: X 6 | B9: 1 | C9: 1 | D9: 1 | E9: 1 | F9: 0.75 | G9: 1 | H9: 1 | I9: 1 | J9: 1 | K9: 1 | L9: 1 | M9: 0.75 | N9: 0.96
A10: X 7 | B10: 0.6 | C10: 0.8 | D10: 1 | E10: 0.6 | F10: 0.8 | G10: 1 | H10: 0.8 | I10: 1 | J10: 1 | K10: 1 | L10: 1 | M10: 0.8 | N10: 0.87
A11: X 8 | B11: 1 | C11: 1 | D11: 1 | E11: 1 | F11: 0.75 | G11: 1 | H11: 0.75 | I11: 0.75 | J11: 1 | K11: 1 | L11: 1 | M11: 1 | N11: 0.94
A12: X 9 | B12: 0.67 | C12: 0.67 | D12: 0.67 | E12: 0.67 | F12: 0.67 | G12: 0.67 | H12: 0.67 | I12: 1 | J12: 0.67 | K12: 0.67 | L12: 0.67 | M12: 0.67 | N12: 0.7
A13: X 10 | B13: 1 | C13: 1 | D13: 1 | E13: 1 | F13: 1 | G13: 1 | H13: 1 | I13: 1 | J13: 1 | K13: 1 | L13: 1 | M13: 1 | N13: 1
A14: 总得分 | B14: 7.99 | C14: 8.27 | D14: 8.47 | E14: 7.32 | F14: 6.97 | G14: 8.42 | H14: 8.02 | I14: 8.8 | J14: 8.22 | K14: 8.92 | L14: 8.67 | M14: 7.02 | N14: 8.09
A15: 排行 | B15: 9 | C15: 6 | D15: 4 | E15: 10 | F15: 12 | G15: 5 | H15: 8 | I15: 2 | J15: 7 | K15: 1 | L15: 3 | M15: 11 | N15: —
A16: 等级 | B16: 好的 | C16: 好的 | D16: 好的 | E16: 好的 | F16: 可以接受 | G16: 好的 | H16: 好的 | I16: 好的 | J16: 好的 | K16: 好的 | L16: 好的 | M16: 好的 | N16: —
B22: =B4 -> 0.8 | C22: =B7 -> 0.75 | D22: =B10 -> 0.6
B23: =B5 -> 0.5 | C23: =B8 -> 1 | D23: =B11 -> 1
B24: =B6 -> 0.67 | C24: =B9 -> 1 | D24: =B12 -> 0.67

Sheet Evaluation
A1: Section 1
A2: 1 | B2: Supervision Objects
B3: Development Enterprises
B4: Compliance with fund use regulations
B5: Transparent reporting and documentation
B6: Municipal and County Construction Departments
B7: Regular inspections and audits
B8: Enforcement of compliance
B9: Commercial Banks
B10: Accurate management of supervision accounts
B11: Timely and correct fund disbursement
A12: 2 | B12: Developer Responsibilities
B13: Apply for pre-sale permits
B14: Establish supervision accounts
B15: Sign supervision agreements
B16: Comply with fund use nodes
B17: Guaranteeing the delivery of housing
A18: 3 | B18: Construction Departments' Responsibilities
B19: Select commercial banks through bidding
B20: Formulate supervision implementation rules
B21: Determine supervision quotas
B22: Supervise fund use
B23: Handle illegal behaviors
A24: 4 | B24: Coordination Mechanism
B25: Determine the service bank through bidding
B26: Guaranteeing the delivery of housing
A27: 5 | B27: Commercial Banks' Responsibilities
B28: Manage supervision accounts
B29: Monitor and allocate funds
B30: Conduct regular reconciliation
A31: 6 | B31: Supervision policy Period
B32: From the issuance of the "Commercial Housing Pre-sale Permit"
B33: To the first registration of property rights aŌ er project completion
A34: 7 | B34: Types of Funds
B35: Deposit
B36: Down Payment
B37: Housing Provident Fund Loans
B38: Mortgage Loans
B39: Other Forms of House Purchase Payments
B40: Any additional payments related to the purchase
...

Sheet Evaluation-transfer
B1: X1 | E1: X2 | I1: X3 | L1: X4 | N1: X5 | S1: X6 | V1: X7 | AA1: X8 | AC1: X9 | AL1: Original Column | AM1: New Column
B2: X1: 1 | C2: X1: 2 | D2: X1: 3 | E2: X2: 1 | F2: X2: 2 | G2: X2: 3 | H2: X2: 4 | I2: X3: 1 | J2: X3: 2 | K2: X3: 3 | L2: X4: 1 | M2: X4: 2 | N2: X5: 1 | O2: X5: 2 | P2: X5: 3 | Q2: X5: 4 | R2: X5: 5 | S2: X6: 1 | T2: X6: 2 | U2: X6: 3 | V2: X7: 1 | W2: X7: 2 | X2: X7: 3 | Y2: X7: 4 | Z2: X7: 5 | AA2: X8: 1 | AB2: X8: 2 | AC2: X9: 1 | AD2: X9: 2 | AE2: X9: 3 | AF2: X9: 4 | AG2: X9: 5 | AH2: X10 | AL2: Main Indicators and Variables | AM2: Main Indicators and Variables
A3: P1 | B3: 0 | C3: 0 | D3: 1 | E3: 0 | F3: 0 | G3: 0 | H3: 0 | I3: 0 | J3: 0 | K3: 1 | L3: 1 | M3: 0 | N3: 1 | O3: 1 | P3: 1 | Q3: 0 | R3: 1 | S3: 1 | T3: 1 | U3: 0 | V3: 0 | W3: 0 | X3: 0 | Y3: 0 | Z3: 0 | AA3: 0 | AB3: 0 | AC3: 1 | AD3: 0 | AE3: 1 | AF3: 0 | AG3: 0 | AH3: 0 | AL3: Sub Indicators and Variables | AM3: Sub Indicators and Variables
A4: P2 | B4: 0 | C4: 1 | D4: 0 | E4: 0 | F4: 0 | G4: 0 | H4: 1 | I4: 0 | J4: 0 | K4: 0 | L4: 1 | M4: 0 | N4: 1 | O4: 1 | P4: 1 | Q4: 1 | R4: 1 | S4: 1 | T4: 0 | U4: 0 | V4: 1 | W4: 1 | X4: 1 | Y4: 0 | Z4: 1 | AA4: 0 | AB4: 0 | AC4: 0 | AD4: 0 | AE4: 1 | AF4: 0 | AG4: 0 | AH4: 0 | AL4: Chinese cities' name | AM4: English cities' name | AN4: # | AO4: Chinese cities' name | AP4: English cities' name | AQ4: # | AR4: Chinese cities' name | AS4: English cities' name | AT4: #
A5: P3 | B5: 1 | C5: 0 | D5: 0 | E5: 0 | F5: 0 | G5: 1 | H5: 0 | I5: 0 | J5: 3 | K5: 1 | L5: 1 | M5: 0 | N5: 2 | O5: 2 | P5: 1 | Q5: 2 | R5: 1 | S5: 1 | T5: 1 | U5: 1 | V5: 1 | W5: 2 | X5: 0 | Y5: 1 | Z5: 0 | AA5: 1 | AB5: 0 | AC5: 2 | AD5: 0 | AE5: 1 | AF5: 0 | AG5: 0 | AH5: 0 | AL5: 白沙县 | AM5: Baisha County | AN5: P1 | AO5: 九江市 | AP5: Jiujiang City | AQ5: P15 | AR5: 韶关 | AS5: Shaoguan | AT5: P29
A6: P4 | B6: 0 | C6: 0 | D6: 1 | E6: 0 | F6: 0 | G6: 0 | H6: 1 | I6: 0 | J6: 1 | K6: 0 | L6: 1 | M6: 0 | N6: 0 | O6: 1 | P6: 0 | Q6: 1 | R6: 2 | S6: 2 | T6: 1 | U6: 1 | V6: 1 | W6: 0 | X6: 0 | Y6: 0 | Z6: 0 | AA6: 0 | AB6: 0 | AC6: 1 | AD6: 0 | AE6: 1 | AF6: 1 | AG6: 0 | AH6: 0 | AL6: 北海市 | AM6: Beihai City | AN6: P2 | AO6: 兰州 | AP6: Lanzhou | AQ6: P16 | AR6: 深圳市 | AS6: Shenzhen | AT6: P30
A7: P5 | B7: 0 | C7: 1 | D7: 0 | E7: 1 | F7: 0 | G7: 0 | H7: 0 | I7: 0 | J7: 1 | K7: 0 | L7: 1 | M7: 0 | N7: 0 | O7: 1 | P7: 0 | Q7: 1 | R7: 2 | S7: 2 | T7: 2 | U7: 0 | V7: 1 | W7: 0 | X7: 0 | Y7: 0 | Z7: 0 | AA7: 0 | AB7: 0 | AC7: 0 | AD7: 0 | AE7: 0 | AF7: 0 | AG7: 0 | AH7: 0 | AL7: 北京市 | AM7: Beijing | AN7: P3 | AO7: 乐东县 | AP7: Ledong County | AQ7: P17 | AR7: 万宁市 | AS7: Wanning City | AT7: P31
A8: P6 | B8: 1 | C8: 0 | D8: 0 | E8: 0 | F8: 0 | G8: 0 | H8: 1 | I8: 0 | J8: 0 | K8: 0 | L8: 1 | M8: 0 | N8: 0 | O8: 0 | P8: 0 | Q8: 0 | R8: 0 | S8: 2 | T8: 0 | U8: 0 | V8: 1 | W8: 0 | X8: 1 | Y8: 1 | Z8: 1 | AA8: 0 | AB8: 1 | AC8: 1 | AD8: 0 | AE8: 1 | AF8: 0 | AG8: 0 | AH8: 0 | AL8: 澄迈县 | AM8: Chengmai County | AN8: P4 | AO8: 乐山市 | AP8: Leshan City | AQ8: P18 | AR8: 文昌市 | AS8: Wenchang City | AT8: P32
A9: P7 | B9: 0 | C9: 0 | D9: 1 | E9: 0 | F9: 1 | G9: 0 | H9: 0 | I9: 0 | J9: 0 | K9: 0 | L9: 1 | M9: 0 | N9: 0 | O9: 2 | P9: 2 | Q9: 2 | R9: 2 | S9: 2 | T9: 2 | U9: 0 | V9: 0 | W9: 0 | X9: 0 | Y9: 0 | Z9: 0 | AA9: 0 | AB9: 0 | AC9: 0 | AD9: 0 | AE9: 0 | AF9: 0 | AG9: 0 | AH9: 0 | AL9: 儋州市 | AM9: Danzhou City | AN9: P5 | AO9: 丽水市 | AP9: Lishui City | AQ9: P19 | AR9: 五指山 | AS9: Wuzhishan | AT9: P33
A10: P8 | B10: 0 | C10: 1 | D10: 0 | E10: 0 | F10: 1 | G10: 0 | H10: 0 | I10: 0 | J10: 1 | K10: 3 | L10: 1 | M10: 0 | N10: 0 | O10: 2 | P10: 1 | Q10: 1 | R10: 1 | S10: 4 | T10: 3 | U10: 0 | V10: 3 | W10: 1 | X10: 1 | Y10: 1 | Z10: 1 | AA10: 1 | AB10: 0 | AC10: 0 | AD10: 1 | AE10: 1 | AF10: 0 | AG10: 0 | AH10: 1 | AL10: 定安县 | AM10: Ding'an County | AN10: P6 | AO10: 临高 | AP10: Lingao | AQ10: P20 | AR10: 信阳市 | AS10: Xinyang City | AT10: P34
A11: P9 | B11: 0 | C11: 1 | D11: 0 | E11: 0 | F11: 1 | G11: 0 | H11: 0 | I11: 0 | J11: 1 | K11: 2 | L11: 1 | M11: 0 | N11: 1 | O11: 2 | P11: 2 | Q11: 2 | R11: 2 | S11: 1 | T11: 0 | U11: 0 | V11: 1 | W11: 1 | X11: 0 | Y11: 1 | Z11: 0 | AA11: 1 | AB11: 0 | AC11: 0 | AD11: 0 | AE11: 0 | AF11: 0 | AG11: 0 | AH11: 1 | AL11: 东方市 | AM11: Dongfang City | AN11: P7 | AO11: 陵水 | AP11: Lingshui | AQ11: P21 | AR11: 义乌 | AS11: Yiwu | AT11: P35
A12: P10 | B12: 0 | C12: 1 | D12: 0 | E12: 0 | F12: 1 | G12: 0 | H12: 0 | I12: 0 | J12: 1 | K12: 0 | L12: 2 | M12: 0 | N12: 1 | O12: 2 | P12: 2 | Q12: 2 | R12: 1 | S12: 1 | T12: 1 | U12: 0 | V12: 0 | W12: 1 | X12: 0 | Y12: 0 | Z12: 0 | AA12: 0 | AB12: 0 | AC12: 1 | AD12: 0 | AE12: 0 | AF12: 0 | AG12: 0 | AH12: 2 | AL12: 东莞 | AM12: Dongguan | AN12: P8 | AO12: 六安 | AP12: Lu'an | AQ12: P22 | AR12: 肇庆市 | AS12: Zhaoqing City | AT12: P36
A13: P11 | B13: 0 | C13: 1 | D13: 0 | E13: 0 | F13: 0 | G13: 0 | H13: 1 | I13: 0 | J13: 0 | K13: 0 | L13: 0 | M13: 1 | N13: 0 | O13: 1 | P13: 1 | Q13: 1 | R13: 0 | S13: 1 | T13: 2 | U13: 0 | V13: 1 | W13: 1 | X13: 0 | Y13: 0 | Z13: 0 | AA13: 0 | AB13: 0 | AC13: 0 | AD13: 0 | AE13: 0 | AF13: 0 | AG13: 0 | AH13: 0 | AL13: 东营市 | AM13: Dongying City | AN13: P9 | AO13: 清远市 | AP13: Qingyuan City | AQ13: P23 | AR13: 中山 | AS13: Zhongshan | AT13: P37
A14: P12 | B14: 0 | C14: 0 | D14: 0 | E14: 0 | F14: 0 | G14: 0 | H14: 0 | I14: 0 | J14: 1 | K14: 0 | L14: 0 | M14: 0 | N14: 1 | O14: 1 | P14: 1 | Q14: 1 | R14: 1 | S14: 2 | T14: 1 | U14: 0 | V14: 1 | W14: 1 | X14: 0 | Y14: 0 | Z14: 0 | AA14: 0 | AB14: 0 | AC14: 0 | AD14: 0 | AE14: 0 | AF14: 0 | AG14: 0 | AH14: 0 | AL14: 佛山市 | AM14: Foshan City | AN14: P10 | AO14: 琼海市 | AP14: Qionghai City | AQ14: P24 | AR14: 中卫 | AS14: Zhongwei | AT14: P38
A15: P13 | B15: 0 | C15: 1 | D15: 0 | E15: 2 | F15: 0 | G15: 0 | H15: 0 | I15: 0 | J15: 2 | K15: 1 | L15: 0 | M15: 1 | N15: 1 | O15: 1 | P15: 1 | Q15: 1 | R15: 0 | S15: 1 | T15: 1 | U15: 0 | V15: 0 | W15: 1 | X15: 0 | Y15: 0 | Z15: 0 | AA15: 0 | AB15: 0 | AC15: 0 | AD15: 0 | AE15: 0 | AF15: 0 | AG15: 0 | AH15: 0 | AL15: 广州市 | AM15: Guangzhou | AN15: P11 | AO15: 琼中县 | AP15: Qiongzhong County | AQ15: P25 | AR15: 珠海市 | AS15: Zhuhai City | AT15: P39
... A17: P15 | B17: 0 | C17: 1 | D17: 0 | E17: 0 | F17: 0 | G17: 0 | H17: 1 | I17: 0 | J17: 3 | K17: 1 | L17: 1 | M17: 0 | N17: 2 | O17: 1 | P17: 1 | Q17: 3 | R17: 1 | S17: 4 | T17: 1 | U17: 0 | V17: 3 | W17: 2 | X17: 0 | Y17: 0 | Z17: 0 | AA17: 0 | AB17: 0 | AC17: 0 | AD17: 0 | AE17: 0 | AF17: 0 | AG17: 0 | AH17: 0 | AL17: 合肥市 | AM17: Hefei | AN17: P13 | AO17: 上海 | AP17: Shanghai | AQ17: P27 | AR17: 昌江县 | AS17: Changjiang County | AT17: P41
A18: P16 | B18: 0 | C18: 1 | D18: 0 | E18: 0 | F18: 1 | G18: 0 | H18: 0 | I18: 0 | J18: 1 | K18: 0 | L18: 1 | M18: 0 | N18: 2 | O18: 2 | P18: 2 | Q18: 2 | R18: 2 | S18: 1 | T18: 2 | U18: 0 | V18: 1 | W18: 1 | X18: 0 | Y18: 0 | Z18: 0 | AA18: 0 | AB18: 0 | AC18: 1 | AD18: 0 | AE18: 1 | AF18: 0 | AG18: 0 | AH18: 1 | AL18: 惠州 | AM18: Huizhou | AN18: P14 | AO18: 上饶 | AP18: Shangrao | AQ18: P28
A19: P17 | B19: 0 | C19: 0 | D19: 1 | E19: 0 | F19: 0 | G19: 0 | H19: 1 | I19: 0 | J19: 0 | K19: 0 | L19: 1 | M19: 0 | N19: 0 | O19: 1 | P19: 1 | Q19: 1 | R19: 1 | S19: 1 | T19: 0 | U19: 0 | V19: 0 | W19: 0 | X19: 0 | Y19: 0 | Z19: 0 | AA19: 0 | AB19: 0 | AC19: 0 | AD19: 0 | AE19: 0 | AF19: 0 | AG19: 0 | AH19: 0
A20: P18 | B20: 0 | C20: 1 | D20: 0 | E20: 0 | F20: 0 | G20: 1 | H20: 0 | I20: 1 | J20: 0 | K20: 0 | L20: 1 | M20: 0 | N20: 1 | O20: 1 | P20: 1 | Q20: 1 | R20: 1 | S20: 2 | T20: 0 | U20: 0 | V20: 1 | W20: 2 | X20: 0 | Y20: 0 | Z20: 0 | AA20: 0 | AB20: 0 | AC20: 1 | AD20: 0 | AE20: 1 | AF20: 0 | AG20: 0 | AH20: 1
A21: P19 | B21: 1 | C21: 0 | D21: 0 | E21: 0 | F21: 0 | G21: 0 | H21: 1 | I21: 0 | J21: 1 | K21: 0 | L21: 1 | M21: 0 | N21: 0 | O21: 0 | P21: 1 | Q21: 2 | R21: 2 | S21: 1 | T21: 1 | U21: 0 | V21: 0 | W21: 0 | X21: 0 | Y21: 0 | Z21: 0 | AA21: 0 | AB21: 0 | AC21: 0 | AD21: 0 | AE21: 0 | AF21: 0 | AG21: 0 | AH21: 0
A22: P20 | B22: 1 | C22: 0 | D22: 0 | E22: 0 | F22: 0 | G22: 0 | H22: 1 | I22: 0 | J22: 2 | K22: 0 | L22: 1 | M22: 0 | N22: 0 | O22: 0 | P22: 0 | Q22: 0 | R22: 0 | S22: 3 | T22: 1 | U22: 0 | V22: 1 | W22: 0 | X22: 1 | Y22: 0 | Z22: 1 | AA22: 0 | AB22: 0 | AC22: 1 | AD22: 0 | AE22: 1 | AF22: 0 | AG22: 0 | AH22: 0
A23: P21 | B23: 1 | C23: 1 | D23: 0 | E23: 0 | F23: 0 | G23: 0 | H23: 1 | I23: 0 | J23: 0 | K23: 0 | L23: 1 | M23: 0 | N23: 0 | O23: 0 | P23: 0 | Q23: 0 | R23: 0 | S23: 2 | T23: 0 | U23: 0 | V23: 1 | W23: 0 | X23: 1 | Y23: 1 | Z23: 1 | AA23: 0 | AB23: 1 | AC23: 1 | AD23: 0 | AE23: 1 | AF23: 0 | AG23: 0 | AH23: 0
A24: P22 | B24: 0 | C24: 1 | D24: 0 | E24: 0 | F24: 0 | G24: 0 | H24: 1 | I24: 0 | J24: 2 | K24: 1 | L24: 1 | M24: 0 | N24: 1 | O24: 1 | P24: 1 | Q24: 1 | R24: 0 | S24: 2 | T24: 0 | U24: 0 | V24: 1 | W24: 1 | X24: 0 | Y24: 0 | Z24: 0 | AA24: 0 | AB24: 0 | AC24: 0 | AD24: 0 | AE24: 2 | AF24: 0 | AG24: 0 | AH24: 0
A25: P23 | B25: 0 | C25: 1 | D25: 0 | E25: 0 | F25: 1 | G25: 0 | H25: 0 | I25: 1 | J25: 3 | K25: 0 | L25: 0 | M25: 0 | N25: 0 | O25: 1 | P25: 1 | Q25: 2 | R25: 0 | S25: 2 | T25: 1 | U25: 0 | V25: 1 | W25: 1 | X25: 1 | Y25: 0 | Z25: 1 | AA25: 0 | AB25: 0 | AC25: 1 | AD25: 0 | AE25: 2 | AF25: 0 | AG25: 0 | AH25: 1
A26: P24 | B26: 0 | C26: 1 | D26: 0 | E26: 0 | F26: 0 | G26: 0 | H26: 1 | I26: 0 | J26: 1 | K26: 0 | L26: 1 | M26: 0 | N26: 0 | O26: 0 | P26: 1 | Q26: 1 | R26: 1 | S26: 1 | T26: 1 | U26: 0 | V26: 0 | W26: 0 | X26: 0 | Y26: 0 | Z26: 0 | AA26: 0 | AB26: 0 | AC26: 0 | AD26: 0 | AE26: 0 | AF26: 0 | AG26: 0 | AH26: 0
A27: P25 | B27: 0 | C27: 0 | D27: 1 | E27: 1 | F27: 0 | G27: 0 | H27: 0 | I27: 0 | J27: 1 | K27: 1 | L27: 1 | M27: 0 | N27: 1 | O27: 1 | P27: 1 | Q27: 0 | R27: 1 | S27: 2 | T27: 0 | U27: 0 | V27: 2 | W27: 2 | X27: 1 | Y27: 0 | Z27: 1 | AA27: 0 | AB27: 0 | AC27: 1 | AD27: 0 | AE27: 1 | AF27: 0 | AG27: 0 | AH27: 0
A28: P26 | B28: 0 | C28: 1 | D28: 0 | E28: 1 | F28: 0 | G28: 0 | H28: 0 | I28: 2 | J28: 2 | K28: 0 | L28: 0 | M28: 0 | N28: 1 | O28: 1 | P28: 1 | Q28: 1 | R28: 1 | S28: 2 | T28: 1 | U28: 1 | V28: 3 | W28: 0 | X28: 0 | Y28: 0 | Z28: 0 | AA28: 0 | AB28: 0 | AC28: 1 | AD28: 0 | AE28: 1 | AF28: 0 | AG28: 0 | AH28: 0
A29: P27 | B29: 0 | C29: 1 | D29: 0 | E29: 0 | F29: 0 | G29: 1 | H29: 0 | I29: 0 | J29: 0 | K29: 0 | L29: 0 | M29: 1 | N29: 1 | O29: 1 | P29: 1 | Q29: 1 | R29: 0 | S29: 2 | T29: 1 | U29: 1 | V29: 0 | W29: 0 | X29: 0 | Y29: 0 | Z29: 0 | AA29: 0 | AB29: 0 | AC29: 0 | AD29: 0 | AE29: 0 | AF29: 1 | AG29: 0 | AH29: 0
A30: P28 | B30: 0 | C30: 1 | D30: 0 | E30: 0 | F30: 0 | G30: 0 | H30: 1 | I30: 0 | J30: 3 | K30: 2 | L30: 0 | M30: 1 | N30: 0 | O30: 0 | P30: 0 | Q30: 1 | R30: 2 | S30: 0 | T30: 0 | U30: 0 | V30: 1 | W30: 2 | X30: 0 | Y30: 1 | Z30: 0 | AA30: 0 | AB30: 1 | AC30: 0 | AD30: 0 | AE30: 1 | AF30: 0 | AG30: 0 | AH30: 0
... A43: P41 | B43: 1 | C43: 0 | D43: 0 | E43: 0 | F43: 0 | G43: 0 | H43: 1 | I43: 0 | J43: 0 | K43: 1 | L43: 1 | M43: 0 | N43: 0 | O43: 0 | P43: 0 | Q43: 1 | R43: 0 | S43: 3 | T43: 0 | U43: 1 | V43: 1 | W43: 0 | X43: 1 | Y43: 0 | Z43: 1 | AA43: 0 | AB43: 1 | AC43: 1 | AD43: 0 | AE43: 1 | AF43: 0 | AG43: 0 | AH43: 0
B45: =B1 -> X1 | C45: =C1 -> 0 | D45: =D1 -> 0 | E45: =E1 -> X2 | F45: =F1 -> 0 | G45: =G1 -> 0 | H45: =H1 -> 0 | I45: =I1 -> X3 | ... AG45: =AG1 -> 0 | AH45: =AH2 -> X10
A46: =A3 -> P1 | B46: =B3/COUNT($B3:$D3) -> 0 | C46: =C3/COUNT($B3:$D3) -> 0 | D46: =D3/COUNT($B3:$D3) -> 0.33333333 | E46: =E3/COUNT($E3:$H3) -> 0 | F46: =F3/COUNT($E3:$H3) -> 0 | G46: =G3/COUNT($E3:$H3) -> 0 | H46: =H3/COUNT($E3:$H3) -> 0 | I46: =I3/COUNT($I3:$K3) -> 0 | J46: =J3/COUNT($I3:$K3) -> 0 | K46: =K3/COUNT($I3:$K3) -> 0.33333333 | L46: =L3/COUNT($L3:$M3) -> 0.5 | M46: =M3/COUNT($L3:$M3) -> 0 | N46: =N3/COUNT($N3:$R3) -> 0.2 | O46: =O3/COUNT($N3:$R3) -> 0.2 | P46: =P3/COUNT($N3:$R3) -> 0.2 | Q46: =Q3/COUNT($N3:$R3) -> 0 | R46: =R3/COUNT($N3:$R3) -> 0.2 | S46: =S3/COUNT($S3:$U3) -> 0.33333333 | T46: =T3/COUNT($S3:$U3) -> 0.33333333 | U46: =U3/COUNT($S3:$U3) -> 0 | V46: =V3/COUNT($V3:$Z3) -> 0 | W46: =W3/COUNT($V3:$Z3) -> 0 | X46: =X3/COUNT($V3:$Z3) -> 0 | Y46: =Y3/COUNT($V3:$Z3) -> 0 | Z46: =Z3/COUNT($V3:$Z3) -> 0 | AA46: =AA3/COUNT($AA3:$AB3) -> 0 | AB46: =AB3/COUNT($AA3:$AB3) -> 0 | AC46: =AC3/COUNT($AC3:$AG3) -> 0.2 | AD46: =AD3/COUNT($AC3:$AG3) -> 0 | AE46: =AE3/COUNT($AC3:$AG3) -> 0.2 | AF46: =AF3/COUNT($AC3:$AG3) -> 0 | AG46: =AG3/COUNT($AC3:$AG3) -> 0 | AH46: =AH3 -> 0
A47: =A4 -> P2 | B47: =B4/COUNT($B4:$D4) -> 0 | C47: =C4/COUNT($B4:$D4) -> 0.33333333 | D47: =D4/COUNT($B4:$D4) -> 0 | E47: =E4/COUNT($E4:$H4) -> 0 | F47: =F4/COUNT($E4:$H4) -> 0 | G47: =G4/COUNT($E4:$H4) -> 0 | H47: =H4/COUNT($E4:$H4) -> 0.25 | I47: =I4/COUNT($I4:$K4) -> 0 | J47: =J4/COUNT($I4:$K4) -> 0 | K47: =K4/COUNT($I4:$K4) -> 0 | L47: =L4/COUNT($L4:$M4) -> 0.5 | M47: =M4/COUNT($L4:$M4) -> 0 | N47: =N4/COUNT($N4:$R4) -> 0.2 | O47: =O4/COUNT($N4:$R4) -> 0.2 | P47: =P4/COUNT($N4:$R4) -> 0.2 | Q47: =Q4/COUNT($N4:$R4) -> 0.2 | R47: =R4/COUNT($N4:$R4) -> 0.2 | S47: =S4/COUNT($S4:$U4) -> 0.33333333 | T47: =T4/COUNT($S4:$U4) -> 0 | U47: =U4/COUNT($S4:$U4) -> 0 | V47: =V4/COUNT($V4:$Z4) -> 0.2 | W47: =W4/COUNT($V4:$Z4) -> 0.2 | X47: =X4/COUNT($V4:$Z4) -> 0.2 | Y47: =Y4/COUNT($V4:$Z4) -> 0 | Z47: =Z4/COUNT($V4:$Z4) -> 0.2 | AA47: =AA4/COUNT($AA4:$AB4) -> 0 | AB47: =AB4/COUNT($AA4:$AB4) -> 0 | AC47: =AC4/COUNT($AC4:$AG4) -> 0 | AD47: =AD4/COUNT($AC4:$AG4) -> 0 | AE47: =AE4/COUNT($AC4:$AG4) -> 0.2 | AF47: =AF4/COUNT($AC4:$AG4) -> 0 | AG47: =AG4/COUNT($AC4:$AG4) -> 0 | AH47: =AH4 -> 0
A48: =A5 -> P3 | B48: =B5/COUNT($B5:$D5) -> 0.33333333 | C48: =C5/COUNT($B5:$D5) -> 0 | D48: =D5/COUNT($B5:$D5) -> 0 | E48: =E5/COUNT($E5:$H5) -> 0 | F48: =F5/COUNT($E5:$H5) -> 0 | G48: =G5/COUNT($E5:$H5) -> 0.25 | H48: =H5/COUNT($E5:$H5) -> 0 | I48: =I5/COUNT($I5:$K5) -> 0 | J48: =J5/COUNT($I5:$K5) -> 1 | K48: =K5/COUNT($I5:$K5) -> 0.33333333 | L48: =L5/COUNT($L5:$M5) -> 0.5 | M48: =M5/COUNT($L5:$M5) -> 0 | N48: =N5/COUNT($N5:$R5) -> 0.4 | O48: =O5/COUNT($N5:$R5) -> 0.4 | P48: =P5/COUNT($N5:$R5) -> 0.2 | Q48: =Q5/COUNT($N5:$R5) -> 0.4 | R48: =R5/COUNT($N5:$R5) -> 0.2 | S48: =S5/COUNT($S5:$U5) -> 0.33333333 | T48: =T5/COUNT($S5:$U5) -> 0.33333333 | U48: =U5/COUNT($S5:$U5) -> 0.33333333 | V48: =V5/COUNT($V5:$Z5) -> 0.2 | W48: =W5/COUNT($V5:$Z5) -> 0.4 | X48: =X5/COUNT($V5:$Z5) -> 0 | Y48: =Y5/COUNT($V5:$Z5) -> 0.2 | Z48: =Z5/COUNT($V5:$Z5) -> 0 | AA48: =AA5/COUNT($AA5:$AB5) -> 0.5 | AB48: =AB5/COUNT($AA5:$AB5) -> 0 | AC48: =AC5/COUNT($AC5:$AG5) -> 0.4 | AD48: =AD5/COUNT($AC5:$AG5) -> 0 | AE48: =AE5/COUNT($AC5:$AG5) -> 0.2 | AF48: =AF5/COUNT($AC5:$AG5) -> 0 | AG48: =AG5/COUNT($AC5:$AG5) -> 0 | AH48: =AH5 -> 0
A49: =A6 -> P4 | B49: =B6/COUNT($B6:$D6) -> 0 | C49: =C6/COUNT($B6:$D6) -> 0 | D49: =D6/COUNT($B6:$D6) -> 0.33333333 | E49: =E6/COUNT($E6:$H6) -> 0 | F49: =F6/COUNT($E6:$H6) -> 0 | G49: =G6/COUNT($E6:$H6) -> 0 | H49: =H6/COUNT($E6:$H6) -> 0.25 | I49: =I6/COUNT($I6:$K6) -> 0 | J49: =J6/COUNT($I6:$K6) -> 0.33333333 | K49: =K6/COUNT($I6:$K6) -> 0 | L49: =L6/COUNT($L6:$M6) -> 0.5 | M49: =M6/COUNT($L6:$M6) -> 0 | N49: =N6/COUNT($N6:$R6) -> 0 | O49: =O6/COUNT($N6:$R6) -> 0.2 | P49: =P6/COUNT($N6:$R6) -> 0 | Q49: =Q6/COUNT($N6:$R6) -> 0.2 | R49: =R6/COUNT($N6:$R6) -> 0.4 | S49: =S6/COUNT($S6:$U6) -> 0.66666667 | T49: =T6/COUNT($S6:$U6) -> 0.33333333 | U49: =U6/COUNT($S6:$U6) -> 0.33333333 | V49: =V6/COUNT($V6:$Z6) -> 0.2 | W49: =W6/COUNT($V6:$Z6) -> 0 | X49: =X6/COUNT($V6:$Z6) -> 0 | Y49: =Y6/COUNT($V6:$Z6) -> 0 | Z49: =Z6/COUNT($V6:$Z6) -> 0 | AA49: =AA6/COUNT($AA6:$AB6) -> 0 | AB49: =AB6/COUNT($AA6:$AB6) -> 0 | AC49: =AC6/COUNT($AC6:$AG6) -> 0.2 | AD49: =AD6/COUNT($AC6:$AG6) -> 0 | AE49: =AE6/COUNT($AC6:$AG6) -> 0.2 | AF49: =AF6/COUNT($AC6:$AG6) -> 0.2 | AG49: =AG6/COUNT($AC6:$AG6) -> 0 | AH49: =AH6 -> 0
A50: =A7 -> P5 | B50: =B7/COUNT($B7:$D7) -> 0 | C50: =C7/COUNT($B7:$D7) -> 0.33333333 | D50: =D7/COUNT($B7:$D7) -> 0 | E50: =E7/COUNT($E7:$H7) -> 0.25 | F50: =F7/COUNT($E7:$H7) -> 0 | G50: =G7/COUNT($E7:$H7) -> 0 | H50: =H7/COUNT($E7:$H7) -> 0 | I50: =I7/COUNT($I7:$K7) -> 0 | J50: =J7/COUNT($I7:$K7) -> 0.33333333 | K50: =K7/COUNT($I7:$K7) -> 0 | L50: =L7/COUNT($L7:$M7) -> 0.5 | M50: =M7/COUNT($L7:$M7) -> 0 | N50: =N7/COUNT($N7:$R7) -> 0 | O50: =O7/COUNT($N7:$R7) -> 0.2 | P50: =P7/COUNT($N7:$R7) -> 0 | Q50: =Q7/COUNT($N7:$R7) -> 0.2 | R50: =R7/COUNT($N7:$R7) -> 0.4 | S50: =S7/COUNT($S7:$U7) -> 0.66666667 | T50: =T7/COUNT($S7:$U7) -> 0.66666667 | U50: =U7/COUNT($S7:$U7) -> 0 | V50: =V7/COUNT($V7:$Z7) -> 0.2 | W50: =W7/COUNT($V7:$Z7) -> 0 | X50: =X7/COUNT($V7:$Z7) -> 0 | Y50: =Y7/COUNT($V7:$Z7) -> 0 | Z50: =Z7/COUNT($V7:$Z7) -> 0 | AA50: =AA7/COUNT($AA7:$AB7) -> 0 | AB50: =AB7/COUNT($AA7:$AB7) -> 0 | AC50: =AC7/COUNT($AC7:$AG7) -> 0 | AD50: =AD7/COUNT($AC7:$AG7) -> 0 | AE50: =AE7/COUNT($AC7:$AG7) -> 0 | AF50: =AF7/COUNT($AC7:$AG7) -> 0 | AG50: =AG7/COUNT($AC7:$AG7) -> 0 | AH50: =AH7 -> 0
A51: =A8 -> P6 | B51: =B8/COUNT($B8:$D8) -> 0.33333333 | C51: =C8/COUNT($B8:$D8) -> 0 | D51: =D8/COUNT($B8:$D8) -> 0 | E51: =E8/COUNT($E8:$H8) -> 0 | F51: =F8/COUNT($E8:$H8) -> 0 | G51: =G8/COUNT($E8:$H8) -> 0 | H51: =H8/COUNT($E8:$H8) -> 0.25 | I51: =I8/COUNT($I8:$K8) -> 0 | J51: =J8/COUNT($I8:$K8) -> 0 | K51: =K8/COUNT($I8:$K8) -> 0 | L51: =L8/COUNT($L8:$M8) -> 0.5 | M51: =M8/COUNT($L8:$M8) -> 0 | N51: =N8/COUNT($N8:$R8) -> 0 | O51: =O8/COUNT($N8:$R8) -> 0 | P51: =P8/COUNT($N8:$R8) -> 0 | Q51: =Q8/COUNT($N8:$R8) -> 0 | R51: =R8/COUNT($N8:$R8) -> 0 | S51: =S8/COUNT($S8:$U8) -> 0.66666667 | T51: =T8/COUNT($S8:$U8) -> 0 | U51: =U8/COUNT($S8:$U8) -> 0 | V51: =V8/COUNT($V8:$Z8) -> 0.2 | W51: =W8/COUNT($V8:$Z8) -> 0 | X51: =X8/COUNT($V8:$Z8) -> 0.2 | Y51: =Y8/COUNT($V8:$Z8) -> 0.2 | Z51: =Z8/COUNT($V8:$Z8) -> 0.2 | AA51: =AA8/COUNT($AA8:$AB8) -> 0 | AB51: =AB8/COUNT($AA8:$AB8) -> 0.5 | AC51: =AC8/COUNT($AC8:$AG8) -> 0.2 | AD51: =AD8/COUNT($AC8:$AG8) -> 0 | AE51: =AE8/COUNT($AC8:$AG8) -> 0.2 | AF51: =AF8/COUNT($AC8:$AG8) -> 0 | AG51: =AG8/COUNT($AC8:$AG8) -> 0 | AH51: =AH8 -> 0
A52: =A9 -> P7 | B52: =B9/COUNT($B9:$D9) -> 0 | C52: =C9/COUNT($B9:$D9) -> 0 | D52: =D9/COUNT($B9:$D9) -> 0.33333333 | E52: =E9/COUNT($E9:$H9) -> 0 | F52: =F9/COUNT($E9:$H9) -> 0.25 | G52: =G9/COUNT($E9:$H9) -> 0 | H52: =H9/COUNT($E9:$H9) -> 0 | I52: =I9/COUNT($I9:$K9) -> 0 | J52: =J9/COUNT($I9:$K9) -> 0 | K52: =K9/COUNT($I9:$K9) -> 0 | L52: =L9/COUNT($L9:$M9) -> 0.5 | M52: =M9/COUNT($L9:$M9) -> 0 | N52: =N9/COUNT($N9:$R9) -> 0 | O52: =O9/COUNT($N9:$R9) -> 0.4 | P52: =P9/COUNT($N9:$R9) -> 0.4 | Q52: =Q9/COUNT($N9:$R9) -> 0.4 | R52: =R9/COUNT($N9:$R9) -> 0.4 | S52: =S9/COUNT($S9:$U9) -> 0.66666667 | T52: =T9/COUNT($S9:$U9) -> 0.66666667 | U52: =U9/COUNT($S9:$U9) -> 0 | V52: =V9/COUNT($V9:$Z9) -> 0 | W52: =W9/COUNT($V9:$Z9) -> 0 | X52: =X9/COUNT($V9:$Z9) -> 0 | Y52: =Y9/COUNT($V9:$Z9) -> 0 | Z52: =Z9/COUNT($V9:$Z9) -> 0 | AA52: =AA9/COUNT($AA9:$AB9) -> 0 | AB52: =AB9/COUNT($AA9:$AB9) -> 0 | AC52: =AC9/COUNT($AC9:$AG9) -> 0 | AD52: =AD9/COUNT($AC9:$AG9) -> 0 | AE52: =AE9/COUNT($AC9:$AG9) -> 0 | AF52: =AF9/COUNT($AC9:$AG9) -> 0 | AG52: =AG9/COUNT($AC9:$AG9) -> 0 | AH52: =AH9 -> 0
A53: =A10 -> P8 | B53: =B10/COUNT($B10:$D10) -> 0 | C53: =C10/COUNT($B10:$D10) -> 0.33333333 | D53: =D10/COUNT($B10:$D10) -> 0 | E53: =E10/COUNT($E10:$H10) -> 0 | F53: =F10/COUNT($E10:$H10) -> 0.25 | G53: =G10/COUNT($E10:$H10) -> 0 | H53: =H10/COUNT($E10:$H10) -> 0 | I53: =I10/COUNT($I10:$K10) -> 0 | J53: =J10/COUNT($I10:$K10) -> 0.33333333 | K53: =K10/COUNT($I10:$K10) -> 1 | L53: =L10/COUNT($L10:$M10) -> 0.5 | M53: =M10/COUNT($L10:$M10) -> 0 | N53: =N10/COUNT($N10:$R10) -> 0 | O53: =O10/COUNT($N10:$R10) -> 0.4 | P53: =P10/COUNT($N10:$R10) -> 0.2 | Q53: =Q10/COUNT($N10:$R10) -> 0.2 | R53: =R10/COUNT($N10:$R10) -> 0.2 | S53: =S10/COUNT($S10:$U10) -> 1.3333333 | T53: =T10/COUNT($S10:$U10) -> 1 | U53: =U10/COUNT($S10:$U10) -> 0 | V53: =V10/COUNT($V10:$Z10) -> 0.6 | W53: =W10/COUNT($V10:$Z10) -> 0.2 | X53: =X10/COUNT($V10:$Z10) -> 0.2 | Y53: =Y10/COUNT($V10:$Z10) -> 0.2 | Z53: =Z10/COUNT($V10:$Z10) -> 0.2 | AA53: =AA10/COUNT($AA10:$AB10) -> 0.5 | AB53: =AB10/COUNT($AA10:$AB10) -> 0 | AC53: =AC10/COUNT($AC10:$AG10) -> 0 | AD53: =AD10/COUNT($AC10:$AG10) -> 0.2 | AE53: =AE10/COUNT($AC10:$AG10) -> 0.2 | AF53: =AF10/COUNT($AC10:$AG10) -> 0 | AG53: =AG10/COUNT($AC10:$AG10) -> 0 | AH53: =AH10 -> 1
A54: =A11 -> P9 | B54: =B11/COUNT($B11:$D11) -> 0 | C54: =C11/COUNT($B11:$D11) -> 0.33333333 | D54: =D11/COUNT($B11:$D11) -> 0 | E54: =E11/COUNT($E11:$H11) -> 0 | F54: =F11/COUNT($E11:$H11) -> 0.25 | G54: =G11/COUNT($E11:$H11) -> 0 | H54: =H11/COUNT($E11:$H11) -> 0 | I54: =I11/COUNT($I11:$K11) -> 0 | J54: =J11/COUNT($I11:$K11) -> 0.33333333 | K54: =K11/COUNT($I11:$K11) -> 0.66666667 | L54: =L11/COUNT($L11:$M11) -> 0.5 | M54: =M11/COUNT($L11:$M11) -> 0 | N54: =N11/COUNT($N11:$R11) -> 0.2 | O54: =O11/COUNT($N11:$R11) -> 0.4 | P54: =P11/COUNT($N11:$R11) -> 0.4 | Q54: =Q11/COUNT($N11:$R11) -> 0.4 | R54: =R11/COUNT($N11:$R11) -> 0.4 | S54: =S11/COUNT($S11:$U11) -> 0.33333333 | T54: =T11/COUNT($S11:$U11) -> 0 | U54: =U11/COUNT($S11:$U11) -> 0 | V54: =V11/COUNT($V11:$Z11) -> 0.2 | W54: =W11/COUNT($V11:$Z11) -> 0.2 | X54: =X11/COUNT($V11:$Z11) -> 0 | Y54: =Y11/COUNT($V11:$Z11) -> 0.2 | Z54: =Z11/COUNT($V11:$Z11) -> 0 | AA54: =AA11/COUNT($AA11:$AB11) -> 0.5 | AB54: =AB11/COUNT($AA11:$AB11) -> 0 | AC54: =AC11/COUNT($AC11:$AG11) -> 0 | AD54: =AD11/COUNT($AC11:$AG11) -> 0 | AE54: =AE11/COUNT($AC11:$AG11) -> 0 | AF54: =AF11/COUNT($AC11:$AG11) -> 0 | AG54: =AG11/COUNT($AC11:$AG11) -> 0 | AH54: =AH11 -> 1
...

Sheet machine_learning
G1: CNY Yuan per square meter | H1: Months | I1: Months | J1: CNY Yuan per square meter | K1: CNY Yuan per square meter | L1: % | M1: % | S1: Months
B2: 城市 | C2: PMCcode | D2: City | E2: Tier System | F2: Province | G2: City average price | H2: Sales absorption period | I2: Standard construction duration | J2: Peak occupancy cost | K2: Opportunity cost | L2: Opportunity cost as a percentage of average sales price | M2: Peak occupancy costs as a percentage of sales price | N2: ='Evaluation-transfer'!AI88 -> PMC-I | O2: ='Evaluation-transfer'!AI224 -> PMC-T | S2: Standard construction duration
B3: 白沙 | C3: P1 | D3: Baisha | E3: Third Tier | F3: Hainan | G3: 7850 | H3: 109.1 | I3: 27.141667 | J3: 3500 | K3: 44.559244 | L3: 0.0056763368 | M3: 0.44585987 | N3: ='Evaluation-transfer'!AI89 -> 3.0333333 | O3: ='Evaluation-transfer'!AI225 -> 3.0333333 | S3: 27.141667 | T3: 26.5
B4: 北海 | C4: P2 | D4: Beihai | E4: Third Tier | F4: Guangxi | G4: 6800 | H4: 11.524897 | I4: 27.141667 | J4: 2560.1079 | K4: 315.86099 | L4: 0.046450146 | M4: 0.37648646 | N4: ='Evaluation-transfer'!AI90 -> 3.4166667 | O4: ='Evaluation-transfer'!AI226 -> 3.4166667 | S4: 27.141667 | T4: 27.141667
B5: 北京 | C5: P3 | D5: Beijing | E5: First Tier | F5: Beijing | G5: 40094 | H5: 19 | I5: 28.008333 | J5: 5000 | K5: 1175.8517 | L5: 0.029327373 | M5: 0.12470694 | N5: ='Evaluation-transfer'!AI91 -> 6.9166667 | O5: ='Evaluation-transfer'!AI227 -> 5.25 | S5: 28.008333 | T5: 27.1
B6: 澄迈 | C6: P4 | D6: Chengmai | E6: Third Tier | F6: Hainan | G6: 11522 | H6: 54.5 | I6: 27.141667 | J6: 3500 | K6: 498.09375 | L6: 0.0432298 | M6: 0.30376671 | N6: ='Evaluation-transfer'!AI92 -> 4.35 | O6: ='Evaluation-transfer'!AI228 -> 3.8166667 | S6: 27.141667 | T6: 26.5
B7: 儋州 | C7: P5 | D7: Danzhou | E7: Third Tier | F7: Hainan | G7: 10533 | H7: 82.5 | I7: 27.141667 | J7: 1798.1091 | K7: 84.611564 | L7: 0.0080329976 | M7: 0.17071196 | N7: ='Evaluation-transfer'!AI93 -> 3.75 | O7: ='Evaluation-transfer'!AI229 -> 2.8833333 | S7: 27.141667 | T7: 26.5
B8: 定安 | C8: P6 | D8: Dingwan | E8: Third Tier | F8: Hainan | G8: 8030 | H8: 41.5 | I8: 27.141667 | J8: 1315.759 | K8: 67.589864 | L8: 0.0084171687 | M8: 0.16385542 | N8: ='Evaluation-transfer'!AI94 -> 3.45 | O8: ='Evaluation-transfer'!AI230 -> 3.1166667 | S8: 27.141667 | T8: 26.5
B9: 东方 | C9: P7 | D9: Dongfang | E9: Third Tier | F9: Hainan | G9: 12405 | H9: 61.7 | I9: 27.141667 | J9: 1256.5843 | K9: 71.444356 | L9: 0.0057593193 | M9: 0.1012966 | N9: ='Evaluation-transfer'!AI95 -> 4.0166667 | O9: ='Evaluation-transfer'!AI231 -> 2.55 | S9: 27.141667 | T9: 26.5
B10: 东莞 | C10: P8 | D10: Dongguan | E10: Second Tier | F10: Guangdong | G10: 36305 | H10: 25.6 | I10: 27.141667 | J10: 14819.814 | K10: 999.32703 | L10: 0.027525879 | M10: 0.40820312 | N10: ='Evaluation-transfer'!AI96 -> 9.05 | O10: ='Evaluation-transfer'!AI232 -> 6.1166667 | S10: 27.141667 | T10: 27.141667
B11: 东营 | C11: P9 | D11: Dongying | E11: Third Tier | F11: Shandong | G11: 8079 | H11: 52.3 | I11: 28.008333 | J11: 1668.3212 | K11: 133.50045 | L11: 0.016524379 | M11: 0.20650096 | N11: ='Evaluation-transfer'!AI97 -> 6.3166667 | O11: ='Evaluation-transfer'!AI233 -> 5.1833333 | S11: 28.008333 | T11: 28.008333
B12: 佛山 | C12: P10 | D12: Foshan | E12: Second Tier | F12: Guangdong | G12: 18333 | H12: 19.9 | I12: 27.141667 | J12: 1372.6719 | K12: 66.268267 | L12: 0.0036146985 | M12: 0.074874372 | N12: ='Evaluation-transfer'!AI98 -> 6.5833333 | O12: ='Evaluation-transfer'!AI234 -> 4.4833333 | S12: 27.141667 | T12: 25
B13: 广州 | C13: P11 | D13: Guangzhou | E13: First Tier | F13: Guangdong | G13: 37881 | H13: 17.6 | I13: 27.141667 | J13: 6177.1858 | K13: 809.7548 | L13: 0.021376278 | M13: 0.16306818 | N13: ='Evaluation-transfer'!AI99 -> 3.0833333 | O13: ='Evaluation-transfer'!AI235 -> 2.75 | S13: 27.141667 | T13: 24
B14: 海口 | C14: P12 | D14: Haikou | E14: Second Tier | F14: Hainan | G14: 18307 | H14: 19.4 | I14: 27.141667 | J14: 5000 | K14: 427.89905 | L14: 0.023373521 | M14: 0.27311957 | N14: ='Evaluation-transfer'!AI100 -> 2.7333333 | O14: ='Evaluation-transfer'!AI236 -> 2.4 | S14: 27.141667 | T14: 26.5
... B43: 昌江 | C43: P41 | D43: Changjiang | E43: Third Tier | F43: Hainan | G43: 6880 | H43: 18.1 | I43: 27.141667 | J43: 2508.7293 | K43: 131.79381 | L43: 0.019156077 | M43: 0.36464088 | N43: ='Evaluation-transfer'!AI129 -> 4.45 | O43: ='Evaluation-transfer'!AI265 -> 3.7833333 | S43: 27.141667 | T43: 26.5
E50: Total Number | F50: Mean | G50: Standard deviation | H50: Variance | I50: Skewness | J50: Min. value | K50: Q1 | L50: Median | M50: Q3 | N50: Max. value | O50: Range | AB50: Value)
E51: 总数N | F51: 均值 | G51: 标准差 | H51: 方差 | I51: 偏度 | J51: 最小值 | K51: 第一个四分位数(Q1) | L51: 中位数 | M51: 第三个四分位数(Q3) | N51: 最大值 | O51: 极差(最大值-最小值)
B52: Sales absorption period | D52: Third Tier | E52: 24 | F52: 69.94644 | G52: 66.83779 | H52: 4467.2903 | I52: 2.40026 | J52: 6.4 | K52: 21.55 | L52: 54.8 | M52: 95.8 | N52: 318.7 | O52: 312.3
D53: First Tier | E53: 4 | F53: 21.625 | G53: 4.05822 | H53: 16.46917 | I53: 0.32088 | J53: 17.6 | K53: 18.3 | L53: 21.25 | M53: 24.95 | N53: 26.4 | O53: 8.8
D54: Second Tier | E54: 13 | F54: 27.75385 | G54: 14.67904 | H54: 215.47436 | I54: 0.81471 | J54: 7.1 | K54: 19.9 | L54: 22.6 | M54: 34.1 | N54: 55.7 | O54: 48.6
B55: City average sales price | D55: Third Tier | E55: 24 | F55: 9798.625 | G55: 3612.628 | H55: 13051100 | I55: 1.05376 | J55: 4898 | K55: 7012.5 | L55: 8237 | M55: 12144.5 | N55: 19437 | O55: 14539
D56: First Tier | E56: 4 | F56: 52036 | G56: 15137.982 | H56: 229158000 | I56: 0.01147 | J56: 37881 | K56: 38987.5 | L56: 51884.5 | M56: 65084.5 | N56: 66494 | O56: 28613
D57: Second Tier | E57: 13 | F57: 17425.462 | G57: 9032.453 | H57: 81585200 | I57: 0.89379 | J57: 5911 | K57: 10711 | L57: 13988 | M57: 21353 | N57: 36305 | O57: 30394
B58: Standard construction duration | D58: Third Tier | E58: 24 | F58: 27.25 | G58: 0.29279 | H58: 0.08572 | I58: 2.42186 | J58: 27.14167 | K58: 27.14167 | L58: 27.14167 | M58: 27.14167 | N58: 28.00833 | O58: 0.86667
D59: First Tier | E59: 4 | F59: 27.35833 | G59: 0.43333 | H59: 0.18778 | I59: 2 | J59: 27.14167 | K59: 27.14167 | L59: 27.14167 | M59: 27.575 | N59: 28.00833 | O59: 0.86667
D60: Second Tier | E60: 13 | F60: 27.20833 | G60: 0.24037 | H60: 0.05778 | I60: 3.60555 | J60: 27.14167 | K60: 27.14167 | L60: 27.14167 | M60: 27.14167 | N60: 28.00833 | O60: 0.86667

Sheet Randa plot
A2: =machine_learning!C2 -> PMCcode | B2: =machine_learning!E2 -> Tier System | C2: ='Evaluation-transfer'!N271 -> X1 | D2: ='Evaluation-transfer'!O271 -> X2 | E2: ='Evaluation-transfer'!P271 -> X3 | F2: ='Evaluation-transfer'!Q271 -> X4 | G2: ='Evaluation-transfer'!R271 -> X5 | H2: ='Evaluation-transfer'!S271 -> X6 | I2: ='Evaluation-transfer'!T271 -> X7 | J2: ='Evaluation-transfer'!U271 -> X8 | ... M2: ='Evaluation-transfer'!X271 -> PMC-T | O2: =A2 -> PMCcode | P2: =B2 -> Tier System | Q2: ='Evaluation-transfer'!AC271 -> X1 | R2: ='Evaluation-transfer'!AD271 -> X2 | S2: ='Evaluation-transfer'!AE271 -> X3 | T2: ='Evaluation-transfer'!AF271 -> X4 | U2: ='Evaluation-transfer'!AG271 -> X5 | V2: ='Evaluation-transfer'!AH271 -> X6 | W2: ='Evaluation-transfer'!AI271 -> X7 | X2: ='Evaluation-transfer'!AJ271 -> X8 | ... AA2: ='Evaluation-transfer'!AM271 -> PMC-I
A3: =machine_learning!C3 -> P1 | B3: =machine_learning!E3 -> Third Tier | C3: ='Evaluation-transfer'!N272 -> 0.33333333 | D3: ='Evaluation-transfer'!O272 -> 0 | E3: ='Evaluation-transfer'!P272 -> 0.33333333 | F3: ='Evaluation-transfer'!Q272 -> 0.5 | G3: ='Evaluation-transfer'!R272 -> 0.8 | H3: ='Evaluation-transfer'!S272 -> 0.66666667 | I3: ='Evaluation-transfer'!T272 -> 0 | J3: ='Evaluation-transfer'!U272 -> 0 | ... M3: ='Evaluation-transfer'!X272 -> 3.0333333 | O3: =A3 -> P1 | P3: =B3 -> Third Tier | Q3: ='Evaluation-transfer'!AC272 -> 0.33333333 | R3: ='Evaluation-transfer'!AD272 -> 0 | S3: ='Evaluation-transfer'!AE272 -> 0.33333333 | T3: ='Evaluation-transfer'!AF272 -> 0.5 | U3: ='Evaluation-transfer'!AG272 -> 0.8 | V3: ='Evaluation-transfer'!AH272 -> 0.66666667 | W3: ='Evaluation-transfer'!AI272 -> 0 | X3: ='Evaluation-transfer'!AJ272 -> 0 | ... AA3: ='Evaluation-transfer'!AM272 -> 3.0333333
A4: =machine_learning!C4 -> P2 | B4: =machine_learning!E4 -> Third Tier | C4: ='Evaluation-transfer'!N273 -> 0.33333333 | D4: ='Evaluation-transfer'!O273 -> 0.25 | E4: ='Evaluation-transfer'!P273 -> 0 | F4: ='Evaluation-transfer'!Q273 -> 0.5 | G4: ='Evaluation-transfer'!R273 -> 1 | H4: ='Evaluation-transfer'!S273 -> 0.33333333 | I4: ='Evaluation-transfer'!T273 -> 0.8 | J4: ='Evaluation-transfer'!U273 -> 0 | ... M4: ='Evaluation-transfer'!X273 -> 3.4166667 | O4: =A4 -> P2 | P4: =B4 -> Third Tier | Q4: ='Evaluation-transfer'!AC273 -> 0.33333333 | R4: ='Evaluation-transfer'!AD273 -> 0.25 | S4: ='Evaluation-transfer'!AE273 -> 0 | T4: ='Evaluation-transfer'!AF273 -> 0.5 | U4: ='Evaluation-transfer'!AG273 -> 1 | V4: ='Evaluation-transfer'!AH273 -> 0.33333333 | W4: ='Evaluation-transfer'!AI273 -> 0.8 | X4: ='Evaluation-transfer'!AJ273 -> 0 | ... AA4: ='Evaluation-transfer'!AM273 -> 3.4166667
A5: =machine_learning!C5 -> P3 | B5: =machine_learning!E5 -> First Tier | C5: ='Evaluation-transfer'!N274 -> 0.33333333 | D5: ='Evaluation-transfer'!O274 -> 0.25 | E5: ='Evaluation-transfer'!P274 -> 0.66666667 | F5: ='Evaluation-transfer'!Q274 -> 0.5 | G5: ='Evaluation-transfer'!R274 -> 1 | H5: ='Evaluation-transfer'!S274 -> 1 | I5: ='Evaluation-transfer'!T274 -> 0.6 | J5: ='Evaluation-transfer'!U274 -> 0.5 | ... M5: ='Evaluation-transfer'!X274 -> 5.25 | O5: =A5 -> P3 | P5: =B5 -> First Tier | Q5: ='Evaluation-transfer'!AC274 -> 0.33333333 | R5: ='Evaluation-transfer'!AD274 -> 0.25 | S5: ='Evaluation-transfer'!AE274 -> 1.3333333 | T5: ='Evaluation-transfer'!AF274 -> 0.5 | U5: ='Evaluation-transfer'!AG274 -> 1.6 | V5: ='Evaluation-transfer'!AH274 -> 1 | W5: ='Evaluation-transfer'!AI274 -> 0.8 | X5: ='Evaluation-transfer'!AJ274 -> 0.5 | ... AA5: ='Evaluation-transfer'!AM274 -> 6.9166667
A6: =machine_learning!C6 -> P4 | B6: =machine_learning!E6 -> Third Tier | C6: ='Evaluation-transfer'!N275 -> 0.33333333 | D6: ='Evaluation-transfer'!O275 -> 0.25 | E6: ='Evaluation-transfer'!P275 -> 0.33333333 | F6: ='Evaluation-transfer'!Q275 -> 0.5 | G6: ='Evaluation-transfer'!R275 -> 0.6 | H6: ='Evaluation-transfer'!S275 -> 1 | I6: ='Evaluation-transfer'!T275 -> 0.2 | J6: ='Evaluation-transfer'!U275 -> 0 | ... M6: ='Evaluation-transfer'!X275 -> 3.8166667 | O6: =A6 -> P4 | P6: =B6 -> Third Tier | Q6: ='Evaluation-transfer'!AC275 -> 0.33333333 | R6: ='Evaluation-transfer'!AD275 -> 0.25 | S6: ='Evaluation-transfer'!AE275 -> 0.33333333 | T6: ='Evaluation-transfer'!AF275 -> 0.5 | U6: ='Evaluation-transfer'!AG275 -> 0.8 | V6: ='Evaluation-transfer'!AH275 -> 1.3333333 | W6: ='Evaluation-transfer'!AI275 -> 0.2 | X6: ='Evaluation-transfer'!AJ275 -> 0 | ... AA6: ='Evaluation-transfer'!AM275 -> 4.35
A7: =machine_learning!C7 -> P5 | B7: =machine_learning!E7 -> Third Tier | C7: ='Evaluation-transfer'!N276 -> 0.33333333 | D7: ='Evaluation-transfer'!O276 -> 0.25 | E7: ='Evaluation-transfer'!P276 -> 0.33333333 | F7: ='Evaluation-transfer'!Q276 -> 0.5 | G7: ='Evaluation-transfer'!R276 -> 0.6 | H7: ='Evaluation-transfer'!S276 -> 0.66666667 | I7: ='Evaluation-transfer'!T276 -> 0.2 | J7: ='Evaluation-transfer'!U276 -> 0 | ... M7: ='Evaluation-transfer'!X276 -> 2.8833333 | O7: =A7 -> P5 | P7: =B7 -> Third Tier | Q7: ='Evaluation-transfer'!AC276 -> 0.33333333 | R7: ='Evaluation-transfer'!AD276 -> 0.25 | S7: ='Evaluation-transfer'!AE276 -> 0.33333333 | T7: ='Evaluation-transfer'!AF276 -> 0.5 | U7: ='Evaluation-transfer'!AG276 -> 0.8 | V7: ='Evaluation-transfer'!AH276 -> 1.3333333 | W7: ='Evaluation-transfer'!AI276 -> 0.2 | X7: ='Evaluation-transfer'!AJ276 -> 0 | ... AA7: ='Evaluation-transfer'!AM276 -> 3.75
A8: =machine_learning!C8 -> P6 | B8: =machine_learning!E8 -> Third Tier | C8: ='Evaluation-transfer'!N277 -> 0.33333333 | D8: ='Evaluation-transfer'!O277 -> 0.25 | E8: ='Evaluation-transfer'!P277 -> 0 | F8: ='Evaluation-transfer'!Q277 -> 0.5 | G8: ='Evaluation-transfer'!R277 -> 0 | H8: ='Evaluation-transfer'!S277 -> 0.33333333 | I8: ='Evaluation-transfer'!T277 -> 0.8 | J8: ='Evaluation-transfer'!U277 -> 0.5 | ... M8: ='Evaluation-transfer'!X277 -> 3.1166667 | O8: =A8 -> P6 | P8: =B8 -> Third Tier | Q8: ='Evaluation-transfer'!AC277 -> 0.33333333 | R8: ='Evaluation-transfer'!AD277 -> 0.25 | S8: ='Evaluation-transfer'!AE277 -> 0 | T8: ='Evaluation-transfer'!AF277 -> 0.5 | U8: ='Evaluation-transfer'!AG277 -> 0 | V8: ='Evaluation-transfer'!AH277 -> 0.66666667 | W8: ='Evaluation-transfer'!AI277 -> 0.8 | X8: ='Evaluation-transfer'!AJ277 -> 0.5 | ... AA8: ='Evaluation-transfer'!AM277 -> 3.45
A9: =machine_learning!C9 -> P7 | B9: =machine_learning!E9 -> Third Tier | C9: ='Evaluation-transfer'!N278 -> 0.33333333 | D9: ='Evaluation-transfer'!O278 -> 0.25 | E9: ='Evaluation-transfer'!P278 -> 0 | F9: ='Evaluation-transfer'!Q278 -> 0.5 | G9: ='Evaluation-transfer'!R278 -> 0.8 | H9: ='Evaluation-transfer'!S278 -> 0.66666667 | I9: ='Evaluation-transfer'!T278 -> 0 | J9: ='Evaluation-transfer'!U278 -> 0 | ... M9: ='Evaluation-transfer'!X278 -> 2.55 | O9: =A9 -> P7 | P9: =B9 -> Third Tier | Q9: ='Evaluation-transfer'!AC278 -> 0.33333333 | R9: ='Evaluation-transfer'!AD278 -> 0.25 | S9: ='Evaluation-transfer'!AE278 -> 0 | T9: ='Evaluation-transfer'!AF278 -> 0.5 | U9: ='Evaluation-transfer'!AG278 -> 1.6 | V9: ='Evaluation-transfer'!AH278 -> 1.3333333 | W9: ='Evaluation-transfer'!AI278 -> 0 | X9: ='Evaluation-transfer'!AJ278 -> 0 | ... AA9: ='Evaluation-transfer'!AM278 -> 4.0166667
A10: =machine_learning!C10 -> P8 | B10: =machine_learning!E10 -> Second Tier | C10: ='Evaluation-transfer'!N279 -> 0.33333333 | D10: ='Evaluation-transfer'!O279 -> 0.25 | E10: ='Evaluation-transfer'!P279 -> 0.66666667 | F10: ='Evaluation-transfer'!Q279 -> 0.5 | G10: ='Evaluation-transfer'!R279 -> 0.8 | H10: ='Evaluation-transfer'!S279 -> 0.66666667 | I10: ='Evaluation-transfer'!T279 -> 1 | J10: ='Evaluation-transfer'!U279 -> 0.5 | ... M10: ='Evaluation-transfer'!X279 -> 6.1166667 | O10: =A10 -> P8 | P10: =B10 -> Second Tier | Q10: ='Evaluation-transfer'!AC279 -> 0.33333333 | R10: ='Evaluation-transfer'!AD279 -> 0.25 | S10: ='Evaluation-transfer'!AE279 -> 1.3333333 | T10: ='Evaluation-transfer'!AF279 -> 0.5 | U10: ='Evaluation-transfer'!AG279 -> 1 | V10: ='Evaluation-transfer'!AH279 -> 2.3333333 | W10: ='Evaluation-transfer'!AI279 -> 1.4 | X10: ='Evaluation-transfer'!AJ279 -> 0.5 | ... AA10: ='Evaluation-transfer'!AM279 -> 9.05
A11: =machine_learning!C11 -> P9 | B11: =machine_learning!E11 -> Third Tier | C11: ='Evaluation-transfer'!N280 -> 0.33333333 | D11: ='Evaluation-transfer'!O280 -> 0.25 | E11: ='Evaluation-transfer'!P280 -> 0.66666667 | F11: ='Evaluation-transfer'!Q280 -> 0.5 | G11: ='Evaluation-transfer'!R280 -> 1 | H11: ='Evaluation-transfer'!S280 -> 0.33333333 | I11: ='Evaluation-transfer'!T280 -> 0.6 | J11: ='Evaluation-transfer'!U280 -> 0.5 | ... M11: ='Evaluation-transfer'!X280 -> 5.1833333 | O11: =A11 -> P9 | P11: =B11 -> Third Tier | Q11: ='Evaluation-transfer'!AC280 -> 0.33333333 | R11: ='Evaluation-transfer'!AD280 -> 0.25 | S11: ='Evaluation-transfer'!AE280 -> 1 | T11: ='Evaluation-transfer'!AF280 -> 0.5 | U11: ='Evaluation-transfer'!AG280 -> 1.8 | V11: ='Evaluation-transfer'!AH280 -> 0.33333333 | W11: ='Evaluation-transfer'!AI280 -> 0.6 | X11: ='Evaluation-transfer'!AJ280 -> 0.5 | ... AA11: ='Evaluation-transfer'!AM280 -> 6.3166667
A12: =machine_learning!C12 -> P10 | B12: =machine_learning!E12 -> Second Tier | C12: ='Evaluation-transfer'!N281 -> 0.33333333 | D12: ='Evaluation-transfer'!O281 -> 0.25 | E12: ='Evaluation-transfer'!P281 -> 0.33333333 | F12: ='Evaluation-transfer'!Q281 -> 0.5 | G12: ='Evaluation-transfer'!R281 -> 1 | H12: ='Evaluation-transfer'!S281 -> 0.66666667 | I12: ='Evaluation-transfer'!T281 -> 0.2 | J12: ='Evaluation-transfer'!U281 -> 0 | ... M12: ='Evaluation-transfer'!X281 -> 4.4833333 | O12: =A12 -> P10 | P12: =B12 -> Second Tier | Q12: ='Evaluation-transfer'!AC281 -> 0.33333333 | R12: ='Evaluation-transfer'!AD281 -> 0.25 | S12: ='Evaluation-transfer'!AE281 -> 0.33333333 | T12: ='Evaluation-transfer'!AF281 -> 1 | U12: ='Evaluation-transfer'!AG281 -> 1.6 | V12: ='Evaluation-transfer'!AH281 -> 0.66666667 | W12: ='Evaluation-transfer'!AI281 -> 0.2 | X12: ='Evaluation-transfer'!AJ281 -> 0 | ... AA12: ='Evaluation-transfer'!AM281 -> 6.5833333
A13: =machine_learning!C13 -> P11 | B13: =machine_learning!E13 -> First Tier | C13: ='Evaluation-transfer'!N282 -> 0.33333333 | D13: ='Evaluation-transfer'!O282 -> 0.25 | E13: ='Evaluation-transfer'!P282 -> 0 | F13: ='Evaluation-transfer'!Q282 -> 0.5 | G13: ='Evaluation-transfer'!R282 -> 0.6 | H13: ='Evaluation-transfer'!S282 -> 0.66666667 | I13: ='Evaluation-transfer'!T282 -> 0.4 | J13: ='Evaluation-transfer'!U282 -> 0 | ... M13: ='Evaluation-transfer'!X282 -> 2.75 | O13: =A13 -> P11 | P13: =B13 -> First Tier | Q13: ='Evaluation-transfer'!AC282 -> 0.33333333 | R13: ='Evaluation-transfer'!AD282 -> 0.25 | S13: ='Evaluation-transfer'!AE282 -> 0 | T13: ='Evaluation-transfer'!AF282 -> 0.5 | U13: ='Evaluation-transfer'!AG282 -> 0.6 | V13: ='Evaluation-transfer'!AH282 -> 1 | W13: ='Evaluation-transfer'!AI282 -> 0.4 | X13: ='Evaluation-transfer'!AJ282 -> 0 | ... AA13: ='Evaluation-transfer'!AM282 -> 3.0833333
... A43: =machine_learning!C43 -> P41 | B43: =machine_learning!E43 -> Third Tier | C43: ='Evaluation-transfer'!N312 -> 0.33333333 | D43: ='Evaluation-transfer'!O312 -> 0.25 | E43: ='Evaluation-transfer'!P312 -> 0.33333333 | F43: ='Evaluation-transfer'!Q312 -> 0.5 | G43: ='Evaluation-transfer'!R312 -> 0.2 | H43: ='Evaluation-transfer'!S312 -> 0.66666667 | I43: ='Evaluation-transfer'!T312 -> 0.6 | J43: ='Evaluation-transfer'!U312 -> 0.5 | ... M43: ='Evaluation-transfer'!X312 -> 3.7833333 | O43: =A43 -> P41 | P43: =B43 -> Third Tier | Q43: ='Evaluation-transfer'!AC312 -> 0.33333333 | R43: ='Evaluation-transfer'!AD312 -> 0.25 | S43: ='Evaluation-transfer'!AE312 -> 0.33333333 | T43: ='Evaluation-transfer'!AF312 -> 0.5 | U43: ='Evaluation-transfer'!AG312 -> 0.2 | V43: ='Evaluation-transfer'!AH312 -> 1.3333333 | W43: ='Evaluation-transfer'!AI312 -> 0.6 | X43: ='Evaluation-transfer'!AJ312 -> 0.5 | ... AA43: ='Evaluation-transfer'!AM312 -> 4.45
B46: 行标签 | C46: 平均值项:X1 | D46: 平均值项:X2 | E46: 平均值项:X3 | F46: 平均值项:X4 | G46: 平均值项:X5 | H46: 平均值项:X6 | I46: 平均值项:X7 | J46: 平均值项:X8 | K46: 平均值项:X9 | L46: 平均值项:X10 | P46: 行标签 | Q46: 平均值项:X1 | R46: 平均值项:X2 | S46: 平均值项:X3 | T46: 平均值项:X4 | U46: 平均值项:X5 | V46: 平均值项:X6 | W46: 平均值项:X7 | X46: 平均值项:X8 | Y46: 平均值项:X9 | Z46: 平均值项:X10
B47: First Tier | C47: 0.33333333 | D47: 0.3125 | E47: 0.16666667 | F47: 0.375 | G47: 0.65 | H47: 0.75 | I47: 0.3 | J47: 0.125 | K47: 0.2 | L47: 0 | P47: First Tier | Q47: 0.33333333 | R47: 0.3125 | S47: 0.33333333 | T47: 0.375 | U47: 0.8 | V47: 0.91666667 | W47: 0.35 | X47: 0.125 | Y47: 0.25 | Z47: 0
B48: Second Tier | C48: 0.30769231 | D48: 0.23076923 | E48: 0.43589744 | F48: 0.42307692 | G48: 0.81538462 | H48: 0.71794872 | I48: 0.36923077 | J48: 0.076923077 | K48: 0.18461538 | L48: 0.38461538 | P48: Second Tier | Q48: 0.30769231 | R48: 0.26923077 | S48: 0.69230769 | T48: 0.5 | U48: 1.1538462 | V48: 1.1794872 | W48: 0.55384615 | X48: 0.076923077 | Y48: 0.18461538 | Z48: 0.46153846
B49: Third Tier | C49: 0.34722222 | D49: 0.22916667 | E49: 0.27777778 | F49: 0.47916667 | G49: 0.58333333 | H49: 0.5 | I49: 0.49166667 | J49: 0.14583333 | K49: 0.24166667 | L49: 0.20833333 | P49: Third Tier | Q49: 0.34722222 | R49: 0.22916667 | S49: 0.38888889 | T49: 0.47916667 | U49: 0.71666667 | V49: 0.80555556 | W49: 0.59166667 | X49: 0.14583333 | Y49: 0.25833333 | Z49: 0.20833333
B50: 总计 | C50: 0.33333333 | D50: 0.23780488 | E50: 0.31707317 | F50: 0.45121951 | G50: 0.66341463 | H50: 0.59349593 | I50: 0.43414634 | J50: 0.12195122 | K50: 0.2195122 | L50: 0.24390244 | P50: 总计 | Q50: 0.33333333 | R50: 0.25 | S50: 0.4796748 | T50: 0.47560976 | U50: 0.86341463 | V50: 0.93495935 | W50: 0.55609756 | X50: 0.12195122 | Y50: 0.23414634 | Z50: 0.26829268

Sheet 房地产销售面积
B3: 指标 | C3: 45413 | D3: 45383 | E3: 45352 | F3: 45323 | G3: 45292 | H3: 45261 | I3: 45231 | J3: 45200 | K3: 45170 | L3: 45139 | M3: 45108 | N3: 45078 | O3: 45047 | P3: 45017 | Q3: 44986 | R3: 44958 | S3: 44927 | T3: 44896 | U3: 44866 | V3: 44835 | W3: 44805 | X3: 44774 | Y3: 44743 | Z3: 44713 | AA3: 44682 | AB3: 44652 | AC3: 44621 | AD3: 44593 | AE3: 44562 | AF3: 44531 | AG3: 44501 | AH3: 44470 | AI3: 44440 | AJ3: 44409 | AK3: 44378 | AL3: 44348
B4: 商品住宅销售面积
B5: 累计值(万平方米) | C5: 30744.16 | D5: 24507.14 | E5: 18941.9 | F5: 9558.82 | H5: 94796.35 | I5: 85964.5 | J5: 79385.98 | K5: 72769.59 | L5: 63811.11 | M5: 57622.54 | N5: 51592.34 | O5: 40663.17 | P5: 32965.87 | Q5: 26251.39 | R5: 13387.18 | T5: 114630.65 | U5: 102726.84 | V5: 94129.37 | W5: 85758.17 | X5: 74402.56 | Y5: 66087.03 | Z5: 58056.89 | AA5: 42902.6 | AB5: 33721.72 | AC5: 26304.59 | AD5: 13462.26 | AF5: 156532.17 | AG5: 139156.19 | AH5: 126419.25 | AI5: 115431.87 | AJ5: 101606.71 | AK5: 90597.93 | AL5: 79081.42
B6: 商品住宅销售面积
B7: 累计增长(%) | C7: -23.6 | D7: -23.8 | E7: -23.4 | F7: -24.8 | H7: -8.2 | I7: -7.3 | J7: -6.8 | K7: -6.3 | L7: -5.5 | M7: -4.3 | N7: -2.8 | O7: 2.3 | P7: 2.7 | Q7: 1.4 | R7: -0.6 | T7: -26.8 | U7: -26.2 | V7: -25.5 | W7: -25.7 | X7: -26.8 | Y7: -27.1 | Z7: -26.6 | AA7: -28.1 | AB7: -25.4 | AC7: -18.6 | AD7: -13.8 | AF7: 1.1 | AG7: 4.4 | AH7: 7.1 | AI7: 11.4 | AJ7: 16.5 | AK7: 22.7 | AL7: 29.4
B8: 商品住宅现房销售面积
B9: 累计值(万平方米) | C9: 8239.06 | D9: 6594.56 | E9: 5095.59 | F9: 2530.27 | H9: 17765.24 | I9: 15643.06 | J9: 14297.21 | K9: 12992.43 | L9: 11105.61 | M9: 9859.96 | N9: 8715.02 | O9: 6729.16 | P9: 5528.71 | Q9: 4455.69 | R9: 2174.7 | T9: 15974.38 | U9: 14010.42 | V9: 12916.77 | W9: 11818.09 | X9: 10284.7 | Y9: 9157.69 | Z9: 8083.33 | AA9: 5699.66 | AB9: 4439.28 | AC9: 3446.67 | AD9: 1812.26 | AF9: 16356.74 | AG9: 13976.18 | AH9: 12452.23 | AI9: 11270.76 | AJ9: 9691.05 | AK9: 8635.87 | AL9: 7502.96
B10: 商品住宅现房销售面积
B11: 累计增长(%) | C11: 23.8 | D11: 22.6 | E11: 21.2 | F11: 22.3 | H11: 22.7 | I11: 23.2 | J11: 21.9 | K11: 21.2 | L11: 18.8 | M11: 17.9 | N11: 17.5 | O11: 26.5 | P11: 30.5 | Q11: 30.3 | R11: 20 | T11: -2.3 | U11: 0.2 | V11: 3.7 | W11: 4.9 | X11: 6.1 | Y11: 6 | Z11: 7.7 | AA11: 4 | AB11: 5.3 | AC11: 13.3 | AD11: 17.1 | AF11: 3.9 | AG11: 4.1 | AH11: 5.4 | AI11: 8.2 | AJ11: 10 | AK11: 13.7 | AL11: 17.5
B12: 商品住宅期房销售面积
B13: 累计值(万平方米) | C13: 22505.1 | D13: 17912.59 | E13: 13846.31 | F13: 7028.55 | H13: 77031.11 | I13: 70321.44 | J13: 65088.77 | K13: 59777.16 | L13: 52705.5 | M13: 47762.57 | N13: 42877.32 | O13: 33934.01 | P13: 27437.16 | Q13: 21795.71 | R13: 11212.48 | T13: 98656.28 | U13: 88716.42 | V13: 81212.6 | W13: 73940.08 | X13: 64117.86 | Y13: 56929.34 | Z13: 49973.56 | AA13: 37202.93 | AB13: 29282.44 | AC13: 22857.92 | AD13: 11650 | AF13: 140175.43 | AG13: 125180.01 | AH13: 113967.02 | AI13: 104161.11 | AJ13: 91915.67 | AK13: 81962.06 | AL13: 71578.46
B14: 商品住宅期房销售面积
B17: 指标 | C17: 45413 | D17: 45383 | E17: 45352 | F17: 45323 | G17: 45261 | H17: 45231 | I17: 45200 | J17: 45170 | K17: 45139 | L17: 45108 | M17: 45078 | N17: 45047 | O17: 45017 | P17: 44986 | Q17: 44958 | R17: 44896 | S17: 44866 | T17: 44835 | U17: 44805 | V17: 44774 | W17: 44743 | X17: 44713 | Y17: 44682 | Z17: 44652 | AA17: 44621 | AB17: 44593 | AC17: 44531 | AD17: 44501 | AE17: 44470 | AF17: 44440 | AG17: 44409 | AH17: 44378 | AI17: 44348
B18: 商品住宅施工面积
B19: 累计值(万平方米) | C19: 481557.1 | D19: 480646.6 | E19: 474580.41 | F19: 466635.99 | G19: 589884.26 | H19: 585309.35 | I19: 579361.46 | J19: 574249.97 | K19: 567791.72 | L19: 563025.82 | M19: 557083.19 | N19: 548474.66 | O19: 542968.14 | P19: 538214.33 | Q19: 527695.21 | R19: 639695.94 | S19: 633915.74 | T19: 628277.72 | U19: 621201.24 | V19: 613604.38 | W19: 607028.94 | X19: 599429.46 | Y19: 586918.32 | Z19: 577691.56 | AA19: 569044.86 | AB19: 553513.53 | AC19: 690319.37 | AD19: 679539.72 | AE19: 667801.09 | AF19: 656884.07 | AG19: 644335.62 | AH19: 631071.97 | AI19: 617479.66
B20: 商品住宅施工面积
B21: 累计增长(%) | C21: -12.2 | D21: -11.4 | E21: -11.7 | F21: -11.4 | G21: -7.7 | H21: -7.6 | I21: -7.7 | J21: -7.4 | K21: -7.3 | L21: -7.1 | M21: -6.9 | N21: -6.5 | O21: -5.9 | P21: -5.4 | Q21: -4.7 | R21: -7.3 | S21: -6.7 | T21: -5.9 | U21: -5.4 | V21: -4.8 | W21: -3.8 | X21: -2.9 | Y21: -1.1 | Z21: -0.1 | AA21: 1.1 | AB21: 2 | AC21: 5.3 | AD21: 6.5 | AE21: 7.4 | AF21: 8.2 | AG21: 8.8 | AH21: 9.4 | AI21: 10.5
B22: 商品住宅新开工施工面积
B23: 累计值(万平方米) | C23: 21759.93 | D23: 17005.67 | E23: 12534.02 | F23: 6795.71 | G23: 69285.61 | H23: 63737.03 | I23: 57658.9 | J23: 52511.64 | K23: 46636.07 | L23: 41546.49 | M23: 36339.64 | N23: 29009.79 | O23: 22899.88 | P23: 17719.09 | Q23: 9891.04 | R23: 88135.08 | S23: 81734.35 | T23: 75934.15 | U23: 69482.75 | V23: 62413.69 | W23: 55918.75 | X23: 48800.48 | Y23: 37782.31 | Z23: 28876.56 | AA23: 21558.38 | AB23: 10835.67 | AC23: 146378.56 | AD23: 135017.36 | AE23: 123480.57 | AF23: 113374.46 | AG23: 100765.33 | AH23: 88473.99 | AI23: 75514.87
B24: 商品住宅新开工施工面积
B25: 累计增长(%) | C25: -25 | D25: -25.6 | E25: -28.7 | F25: -30.6 | G25: -20.9 | H25: -21.5 | I25: -23.6 | J25: -23.9 | K25: -24.7 | L25: -25 | M25: -24.9 | N25: -22.7 | O25: -20.6 | P25: -17.8 | Q25: -8.7 | R25: -39.8 | S25: -39.5 | T25: -38.5 | U25: -38.7 | V25: -38.1 | W25: -36.8 | X25: -35.4 | Y25: -31.9 | Z25: -28.4 | AA25: -20.3 | AB25: -14.9 | AC25: -10.9 | AD25: -8.4 | AE25: -6.8 | AF25: -3.3 | AG25: -1.7 | AH25: 0.4 | AI25: 5.5
B26: 商品住宅竣工面积
B27: 累计值(万平方米) | C27: 16199.37 | D27: 13745.79 | E27: 11147.95 | F27: 7694 | G27: 72432.59 | H27: 47580.71 | I27: 40079.28 | J27: 35319.34 | K27: 31775.39 | L27: 27953.67 | M27: 24603.62 | N27: 20194.33 | O27: 17395.98 | P27: 14395.91 | Q27: 9781.5 | R27: 62539.25 | S27: 40441.54 | T27: 33771.43 | U27: 29595.36 | V27: 26737.46 | W27: 23279.5 | X27: 20858.26 | Y27: 17049.73 | Z27: 14661.72 | AA27: 12322.65 | AB27: 8914.78 | AC27: 73016.2 | AD27: 49582.28 | AE27: 41415.46 | AF27: 36816.18 | AG27: 33771.05 | AH27: 30125.2 | AI27: 26253.82
B28: 商品住宅竣工面积 | C28: =C27 -> 16199.37 | G28: =G27-H27 -> 24851.88 | AA28: =AA27 -> 12322.65
B36: 45413 | C36: 45078 | D36: 竣备 | E36: =C27+N27 -> 36393.7
B37: 44531 | C37: 44896 | D37: 销售 | E37: =T13 -> 98656.28 | F37: =E36/E37 -> 0.3688939

Sheet matrix
B1: 白沙县 | C1: 北海市 | D1: 北京市 | E1: 澄迈县 | F1: 儋州市 | G1: 定安县 | H1: 东方市 | I1: 东莞 | J1: 东营市 | K1: 佛山市 | L1: 广州市 | M1: 海口市 | N1: 合肥市 | O1: 惠州 | P1: 九江市 | Q1: 兰州 | R1: 乐东县 | S1: 乐山市 | T1: 丽水市 | U1: 临高 | V1: 陵水 | W1: 六安 | X1: 清远市 | Y1: 琼海市 | Z1: 琼中县 | AA1: 汕头市2 | AB1: 上海 | AC1: 上饶 | AD1: 韶关 | AE1: 深圳市 | AF1: 万宁市 | AG1: 文昌市 | AH1: 五指山 | AI1: 信阳市 | AJ1: 义乌 | AK1: 肇庆市 | AL1: 中山 | AM1: 中卫 | AN1: 珠海市 | AO1: 屯昌县 | AP1: 昌江县
A2: 1 : code | B2: 10 | C2: 12 | D2: 20 | E2: 14 | F2: 12 | G2: 9 | H2: 15 | I2: 17 | J2: 13 | K2: 15 | L2: 12 | M2: 6 | N2: 10 | O2: 15 | P2: 26 | Q2: 13 | R2: 2 | S2: 15 | T2: 11 | U2: 14 | V2: 10 | W2: 10 | X2: 16 | Y2: 7 | Z2: 18 | AA2: 18 | AB2: 7 | AC2: 14 | AD2: 10 | AE2: 8 | AF2: 15 | AG2: 12 | AH2: 8 | AI2: 9 | AJ2: 12 | AK2: 15 | AL2: 24 | AM2: 18 | AN2: 12 | AO2: 8 | AP2: 8
